Workbook

Sheet DASHBOARD
A1: APEX TECHNOLOGIES (SAMPLE)
A2: Equity Valuation Cockpit — verdict, fair value, entry zone, quality and timing at a glance.
A3: EQUITY VALUATION COCKPIT • APEX TECHNOLOGIES (SAMPLE) • APEX
B5: V A L U A T I O N V E R D I C T
B6: Current price | C6: =ASSUMPTIONS!$C$6 | F6: =IF(OR(QUALITY!$C$32<1.81,QUALITY!$C$45>-1.78),"HOLD (RISK FLAG)",IF(C10>=$C$24+0.15,"STRONG BUY",IF(C10>=$C$24,"BUY - MEETS BAR",IF(C10>=$C$24-0.15,"HOLD / WATCH","OVERVALUED / AVOID"))))
B7: Blended fair value
B8: Blended fair value | C8: =IF((IF(IFERROR(DCF!$C$43,-1)>0,ASSUMPTIONS!$C$123,0)+IF(IFERROR(DCF!$C$57,-1)>0,ASSUMPTIONS!$C$124,0)+IF(IFERROR(RELATIVE!$C$17,-1)>0,ASSUMPTIONS!$C$125,0)+IF(IFERROR(VALUE_HEURISTICS!$C$8,-1)>0,ASSUMPTIONS!$C$126,0)+IF(IFERROR(VALUE_HEURISTICS!$C$6,-1)>0,ASSUMPTIONS!$C$127,0)+IF(IFERROR(VALUE_HEURISTICS!$C$7,-1)>0,ASSUMPTIONS!$C$128,0))=0,NA(),(IF(IFERROR(DCF!$C$43,-1)>0,DCF!$C$43*ASSUMPTIONS!$C$123,0)+IF(IFERROR(DCF!$C$57,-1)>0,DCF!$C$57*ASSUMPTIONS!$C$124,0)+IF(IFERROR(RELATIVE!$C$17,-1)>0,RELATIVE!$C$17*ASSUMPTIONS!$C$125,0)+IF(IFERROR(VALUE_HEURISTICS!$C$8,-1)>0,VALUE_HEURISTICS!$C$8*ASSUMPTIONS!$C$126,0)+IF(IFERROR(VALUE_HEURISTICS!$C$6,-1)>0,VALUE_HEURISTICS!$C$6*ASSUMPTIONS!$C$127,0)+IF(IFERROR(VALUE_HEURISTICS!$C$7,-1)>0,VALUE_HEURISTICS!$C$7*ASSUMPTIONS!$C$128,0))/(IF(IFERROR(DCF!$C$43,-1)>0,ASSUMPTIONS!$C$123,0)+IF(IFERROR(DCF!$C$57,-1)>0,ASSUMPTIONS!$C$124,0)+IF(IFERROR(RELATIVE!$C$17,-1)>0,ASSUMPTIONS!$C$125,0)+IF(IFERROR(VALUE_HEURISTICS!$C$8,-1)>0,ASSUMPTIONS!$C$126,0)+IF(IFERROR(VALUE_HEURISTICS!$C$6,-1)>0,ASSUMPTIONS!$C$127,0)+IF(IFERROR(VALUE_HEURISTICS!$C$7,-1)>0,ASSUMPTIONS!$C$128,0)))
B9: Upside vs price | C9: =C8/C6-1
B10: Margin of safety | C10: =(C8-C6)/C8 | F10: E N T R Y Z O N E
B11: Altman zone | C11: =QUALITY!$C$33 | F11: Buy below (FV*(1-req MoS)) | G11: =C8*(1-C24)
B12: Beneish flag | C12: =QUALITY!$C$46 | F12: Buy band low (FV*(1-req-10%)) | G12: =C8*(1-C24-0.10)
B13: Piotroski | C13: =QUALITY!$C$24&" / 9" | F13: Buy band high (= buy below) | G13: =C8*(1-C24)
F14: Nearest Fib support | G14: =TIMING!$C$21
B16: S C O R E C H I P S | F16: V A L U A T I O N S U M M A R Y
B17: Piotroski F-Score | C17: =QUALITY!$C$24 | F17: Method | G17: $/sh | H17: Upside
B18: Altman Z | C18: =QUALITY!$C$32 | F18: DCF (FCFF) | G18: =IFERROR(DCF!$C$43,NA()) | H18: =IFERROR(DCF!$C$43/C6-1,NA())
B19: Beneish M | C19: =QUALITY!$C$45 | F19: DCF (FCFE) | G19: =IFERROR(DCF!$C$57,NA()) | H19: =IFERROR(DCF!$C$57/C6-1,NA())
B20: ROIC vs WACC spread | C20: =QUALITY!$C$8-DCF!$C$11 | F20: Relative (P/E & EV/EBITDA) | G20: =IFERROR(RELATIVE!$C$17,NA()) | H20: =IFERROR(RELATIVE!$C$17/C6-1,NA())
F21: EPV | G21: =IFERROR(VALUE_HEURISTICS!$C$8,NA()) | H21: =IFERROR(VALUE_HEURISTICS!$C$8/C6-1,NA())
B22: C O N T E X T & R E G I M E | F22: Graham Number | G22: =IFERROR(VALUE_HEURISTICS!$C$6,NA()) | H22: =IFERROR(VALUE_HEURISTICS!$C$6/C6-1,NA())
B23: Quality tier | C23: =CONTEXT!$C$18 | F23: Graham Formula | G23: =IFERROR(VALUE_HEURISTICS!$C$7,NA()) | H23: =IFERROR(VALUE_HEURISTICS!$C$7/C6-1,NA())
B24: Required MoS (effective) | C24: =CONTEXT!$C$40 | F24: Prob-weighted scenario | G24: =IFERROR(SCENARIO_MC!$C$36,NA()) | H24: =IFERROR(SCENARIO_MC!$C$36/C6-1,NA())
B25: Valuation vs own 10y | C25: =CONTEXT!$C$12 | F25: Monte Carlo median | G25: =IFERROR(SCENARIO_MC!$O$8,NA()) | H25: =IFERROR(SCENARIO_MC!$O$8/C6-1,NA())
B26: Market regime | C26: =CONTEXT!$C$28 | F26: BLENDED FAIR VALUE | G26: =C8 | H26: =C8/C6-1
B27: Meets bar to buy? | C27: =IF(C10>=C24,"YES","NO")
B28: T H E S I S
B29: ="At $"&TEXT(C6,"0.00")&", APEX trades at "&TEXT(C9,"0.0%")&" upside to blended FV of $"&TEXT(C8,"0.00")&" (MoS "&TEXT(C10,"0.0%")&"). "&"ROIC "&IF(QUALITY!$C$8>DCF!$C$11,"exceeds","trails")&" WACC; Altman "&QUALITY!$C$33&", Beneish "&QUALITY!$C$46&", Piotroski "&QUALITY!$C$24&"/9. Buy below $"&TEXT(G11,"0.00")&"."
B31: =IF(QUALITY!$C$24<4,"⚠ Caution: Piotroski below 4 — weak fundamental momentum.",IF(OR(QUALITY!$C$32<1.81,QUALITY!$C$45>-1.78),"⚠ Risk flag active — verdict capped at HOLD.",""))

Sheet ASSUMPTIONS
A1: ASSUMPTIONS
A2: Single source of truth — every gold cell is editable; all other sheets reference these.
A3: EQUITY VALUATION COCKPIT • APEX TECHNOLOGIES (SAMPLE) • APEX
B5: M A R K E T | C5: VALUE | E5: NOTE
B6: Current price ($/sh) | C6: 185 | E6: Live market price per share
B7: Shares outstanding (M) | C7: 1000 | E7: Diluted shares, millions
B8: 52-week high ($) | C8: 230 | E8: 52w high
B9: 52-week low ($) | C9: 140 | E9: 52w low
B10: Swing high ($) | C10: 210 | E10: Recent swing high for Fib
B11: Swing low ($) | C11: 150 | E11: Recent swing low for Fib
B12: 50-day MA ($) | C12: 182 | E12: 50DMA
B13: 200-day MA ($) | C13: 176 | E13: 200DMA
B14: RSI(14) | C14: 55 | E14: Relative strength index
B15: Beta | C15: 1.15 | E15: Levered equity beta
B17: I N C O M E & C A S H F L O W ( T T M ) | C17: VALUE | E17: NOTE
B18: Revenue ($M) | C18: 80000 | E18: TTM revenue, millions
B19: EBIT margin | C19: 0.28 | E19: Operating margin
B20: Tax rate | C20: 0.21 | E20: Effective / marginal tax
B21: D&A (% of revenue) | C21: 0.04 | E21: Depreciation & amortization
B22: CapEx (% of revenue) | C22: 0.05 | E22: Capital expenditure
B23: Change in NWC (% of dRev) | C23: 0.12 | E23: Working-cap investment on YoY rev increase
B24: Interest expense ($M) | C24: 1000 | E24: TTM interest expense
B25: Net income ($M) | C25: 16900 | E25: TTM net income
B27: B A L A N C E S H E E T | C27: VALUE | E27: NOTE
B28: Total debt ($M) | C28: 20000 | E28: Short + long term debt
B29: Cash & equivalents ($M) | C29: 15000 | E29: Cash + ST investments
B30: Book value of equity ($M) | C30: 50000 | E30: Total shareholders equity
B31: Total assets ($M) | C31: 95000 | E31: Total assets
B32: Total current assets ($M) | C32: 38000 | E32: Current assets
B33: Total current liabilities ($M) | C33: 22000 | E33: Current liabilities
B34: Retained earnings ($M) | C34: 30000 | E34: Retained earnings
B35: Total liabilities ($M) | C35: 45000 | E35: Total liabilities
B37: G R O W T H | C37: VALUE | E37: NOTE
B38: Revenue growth yr 1 | C38: 0.12 | E38: Explicit stage growth
B39: Revenue growth yr 2 | C39: 0.11
B40: Revenue growth yr 3 | C40: 0.1
B41: Revenue growth yr 4 | C41: 0.09
B42: Revenue growth yr 5 | C42: 0.08
B43: Terminal growth | C43: 0.03 | E43: Perpetuity growth rate
B45: W A C C I N P U T S | C45: VALUE | E45: NOTE
...

Sheet DCF
A1: DISCOUNTED CASH FLOW
A2: 2-stage FCFF with dual terminal value, FCFE mini-model, and WACC x g sensitivity.
A3: EQUITY VALUATION COCKPIT • APEX TECHNOLOGIES (SAMPLE) • APEX
B5: W A C C B U I L D E R
B6: Cost of equity Ke = Rf + Beta*ERP | C6: =ASSUMPTIONS!$C$46+ASSUMPTIONS!$C$15*ASSUMPTIONS!$C$47
B7: After-tax Kd (pre-tax = int/debt if avail) | C7: =IF(AND(ASSUMPTIONS!$C$24>0,ASSUMPTIONS!$C$28>0),ASSUMPTIONS!$C$24/ASSUMPTIONS!$C$28,ASSUMPTIONS!$C$48)*(1-ASSUMPTIONS!$C$20)
B8: Equity value E = price*shares | C8: =ASSUMPTIONS!$C$6*ASSUMPTIONS!$C$7
B9: Debt value D = total debt | C9: =ASSUMPTIONS!$C$28
B10: V = E + D | C10: =C8+C9
B11: WACC = (E/V)*Ke + (D/V)*Kd_at | C11: =(C8/C10)*C6+(C9/C10)*C7
B12: Net debt = total debt - cash | C12: =ASSUMPTIONS!$C$28-ASSUMPTIONS!$C$29
B14: F C F F 2 - S T A G E P R O J E C T I O N ( $ M )
B15: Line item | C15: Base (t0) | D15: Year 1 | E15: Year 2 | F15: Year 3 | G15: Year 4 | H15: Year 5
B16: Revenue | C16: =ASSUMPTIONS!$C$18 | D16: =C16*(1+ASSUMPTIONS!$C$38) | E16: =D16*(1+ASSUMPTIONS!$C$39) | F16: =E16*(1+ASSUMPTIONS!$C$40) | G16: =F16*(1+ASSUMPTIONS!$C$41) | H16: =G16*(1+ASSUMPTIONS!$C$42)
B17: growth % | D17: =ASSUMPTIONS!$C$38 | E17: =ASSUMPTIONS!$C$39 | F17: =ASSUMPTIONS!$C$40 | G17: =ASSUMPTIONS!$C$41 | H17: =ASSUMPTIONS!$C$42
B18: EBIT | D18: =D16*ASSUMPTIONS!$C$19 | E18: =E16*ASSUMPTIONS!$C$19 | F18: =F16*ASSUMPTIONS!$C$19 | G18: =G16*ASSUMPTIONS!$C$19 | H18: =H16*ASSUMPTIONS!$C$19
B19: NOPAT = EBIT*(1-tax) | D19: =D18*(1-ASSUMPTIONS!$C$20) | E19: =E18*(1-ASSUMPTIONS!$C$20) | F19: =F18*(1-ASSUMPTIONS!$C$20) | G19: =G18*(1-ASSUMPTIONS!$C$20) | H19: =H18*(1-ASSUMPTIONS!$C$20)
B20: D&A | D20: =D16*ASSUMPTIONS!$C$21 | E20: =E16*ASSUMPTIONS!$C$21 | F20: =F16*ASSUMPTIONS!$C$21 | G20: =G16*ASSUMPTIONS!$C$21 | H20: =H16*ASSUMPTIONS!$C$21
B21: CapEx | D21: =-D16*ASSUMPTIONS!$C$22 | E21: =-E16*ASSUMPTIONS!$C$22 | F21: =-F16*ASSUMPTIONS!$C$22 | G21: =-G16*ASSUMPTIONS!$C$22 | H21: =-H16*ASSUMPTIONS!$C$22
B22: Change in NWC | D22: =-(D16-C16)*ASSUMPTIONS!$C$23 | E22: =-(E16-D16)*ASSUMPTIONS!$C$23 | F22: =-(F16-E16)*ASSUMPTIONS!$C$23 | G22: =-(G16-F16)*ASSUMPTIONS!$C$23 | H22: =-(H16-G16)*ASSUMPTIONS!$C$23
B23: FCFF | D23: =D19+D20+D21+D22 | E23: =E19+E20+E21+E22 | F23: =F19+F20+F21+F22 | G23: =G19+G20+G21+G22 | H23: =H19+H20+H21+H22
B24: Discount factor | D24: =1/(1+DCF!$C$11)^1 | E24: =1/(1+DCF!$C$11)^2 | F24: =1/(1+DCF!$C$11)^3 | G24: =1/(1+DCF!$C$11)^4 | H24: =1/(1+DCF!$C$11)^5
B25: PV of FCFF | D25: =D23*D24 | E25: =E23*E24 | F25: =F23*F24 | G25: =G23*G24 | H25: =H23*H24
B26: Sum PV(FCFF) | C26: =SUM(D25:H25)
B27: FCFF base (t0) | C27: =ASSUMPTIONS!$C$18*ASSUMPTIONS!$C$19*(1-ASSUMPTIONS!$C$20)+ASSUMPTIONS!$C$18*ASSUMPTIONS!$C$21-ASSUMPTIONS!$C$18*ASSUMPTIONS!$C$22
B29: T E R M I N A L V A L U E — D U A L M E T H O D
B30: A. Gordon: FCFF5*(1+gt)/(WACC-gt) | C30: =IF(DCF!$C$11<=ASSUMPTIONS!$C$43,0,H23*(1+ASSUMPTIONS!$C$43)/(DCF!$C$11-ASSUMPTIONS!$C$43))
B31: EBITDA Year5 = EBIT5 + D&A5 | C31: =H18+H20
B32: B. Exit multiple: EBITDA5 * exit | C32: =C31*ASSUMPTIONS!$C$60
B33: Discount factor DF5 | C33: =1/(1+DCF!$C$11)^5
B34: PV of TV (Gordon) | C34: =C30*C33
B35: PV of TV (Exit) | C35: =C32*C33
B36: Blended terminal (avg A,B) | C36: =AVERAGE(C30,C32)
B37: PV of blended TV | C37: =C36*C33
B39: E V → E Q U I T Y → P E R - S H A R E
B40: Enterprise value = PV FCFF + PV TV | C40: =C26+C37
B41: less Net debt | C41: =-DCF!$C$12
B42: Equity value | C42: =C40+C41
B43: DCF value per share (FCFF) | C43: =C42/ASSUMPTIONS!$C$7
B44: Upside vs price | C44: =C43/ASSUMPTIONS!$C$6-1
...

Sheet RELATIVE
A1: RELATIVE VALUATION
A2: Implied price from peer multiples vs current multiples; PEG.
A3: EQUITY VALUATION COCKPIT • APEX TECHNOLOGIES (SAMPLE) • APEX
B5: M U L T I P L E S — C U R R E N T V S P E E R → I M P L I E D P R I C E
B6: Method | C6: Current | D6: Peer median | E6: Implied $/sh | F6: Upside %
B7: P/E | C7: =ASSUMPTIONS!$C$6/(ASSUMPTIONS!$C$25/ASSUMPTIONS!$C$7) | D7: =ASSUMPTIONS!$C$52 | E7: =ASSUMPTIONS!$C$52*(ASSUMPTIONS!$C$25/ASSUMPTIONS!$C$7) | F7: =E7/ASSUMPTIONS!$C$6-1
B8: Forward P/E | C8: =ASSUMPTIONS!$C$6/((ASSUMPTIONS!$C$25/ASSUMPTIONS!$C$7)*(1+ASSUMPTIONS!$C$38)) | D8: =ASSUMPTIONS!$C$53 | E8: =ASSUMPTIONS!$C$53*((ASSUMPTIONS!$C$25/ASSUMPTIONS!$C$7)*(1+ASSUMPTIONS!$C$38)) | F8: =E8/ASSUMPTIONS!$C$6-1
B9: EV/EBITDA | C9: =(ASSUMPTIONS!$C$6*ASSUMPTIONS!$C$7+ASSUMPTIONS!$C$28-ASSUMPTIONS!$C$29)/(ASSUMPTIONS!$C$18*ASSUMPTIONS!$C$19+ASSUMPTIONS!$C$18*ASSUMPTIONS!$C$21) | D9: =ASSUMPTIONS!$C$54 | E9: =(ASSUMPTIONS!$C$54*(ASSUMPTIONS!$C$18*ASSUMPTIONS!$C$19+ASSUMPTIONS!$C$18*ASSUMPTIONS!$C$21)-(ASSUMPTIONS!$C$28-ASSUMPTIONS!$C$29))/ASSUMPTIONS!$C$7 | F9: =E9/ASSUMPTIONS!$C$6-1
B10: EV/Sales | C10: =(ASSUMPTIONS!$C$6*ASSUMPTIONS!$C$7+ASSUMPTIONS!$C$28-ASSUMPTIONS!$C$29)/ASSUMPTIONS!$C$18 | D10: =ASSUMPTIONS!$C$55 | E10: =(ASSUMPTIONS!$C$55*ASSUMPTIONS!$C$18-(ASSUMPTIONS!$C$28-ASSUMPTIONS!$C$29))/ASSUMPTIONS!$C$7 | F10: =E10/ASSUMPTIONS!$C$6-1
B11: P/B | C11: =ASSUMPTIONS!$C$6/(ASSUMPTIONS!$C$30/ASSUMPTIONS!$C$7) | D11: =ASSUMPTIONS!$C$56 | E11: =ASSUMPTIONS!$C$56*(ASSUMPTIONS!$C$30/ASSUMPTIONS!$C$7) | F11: =E11/ASSUMPTIONS!$C$6-1
B12: P/FCF | C12: =ASSUMPTIONS!$C$6/(DCF!$C$27/ASSUMPTIONS!$C$7) | D12: =ASSUMPTIONS!$C$57 | E12: =ASSUMPTIONS!$C$57*(DCF!$C$27/ASSUMPTIONS!$C$7) | F12: =E12/ASSUMPTIONS!$C$6-1
B14: P E G
B15: PEG = (P/E)/(g1*100) | C15: =(ASSUMPTIONS!$C$6/(ASSUMPTIONS!$C$25/ASSUMPTIONS!$C$7))/(ASSUMPTIONS!$C$38*100)
B17: Relative blended (P/E & EV/EBITDA) | C17: =AVERAGE(E7,E9)

Sheet VALUE_HEURISTICS
A1: VALUE HEURISTICS
A2: Graham Number & Formula, EPV, Owner Earnings, and the Reverse DCF solver.
A3: EQUITY VALUATION COCKPIT • APEX TECHNOLOGIES (SAMPLE) • APEX
B5: H E U R I S T I C F A I R V A L U E S ( $ / S H )
B6: Graham Number = sqrt(22.5*EPS*BVPS) | C6: =IF(AND((ASSUMPTIONS!$C$25/ASSUMPTIONS!$C$7)>0,(ASSUMPTIONS!$C$30/ASSUMPTIONS!$C$7)>0),SQRT(22.5*(ASSUMPTIONS!$C$25/ASSUMPTIONS!$C$7)*(ASSUMPTIONS!$C$30/ASSUMPTIONS!$C$7)),NA())
B7: Graham Formula = EPS*(8.5+2*g)*4.4/Y | C7: =(ASSUMPTIONS!$C$25/ASSUMPTIONS!$C$7)*(8.5+2*MIN(ASSUMPTIONS!$C$38*100,15))*4.4/(ASSUMPTIONS!$C$49*100)
B8: EPV = NOPAT/WACC - NetDebt (per sh) | C8: =IF(DCF!$C$11<=0,NA(),((ASSUMPTIONS!$C$18*ASSUMPTIONS!$C$19*(1-ASSUMPTIONS!$C$20))/DCF!$C$11-DCF!$C$12)/ASSUMPTIONS!$C$7)
B10: O W N E R E A R N I N G S ( B U F F E T T )
B11: Owner earnings = NI + D&A - maint capex | C11: =ASSUMPTIONS!$C$25+ASSUMPTIONS!$C$18*ASSUMPTIONS!$C$21-0.70*ASSUMPTIONS!$C$18*ASSUMPTIONS!$C$22
B12: (maint capex ~ 70% of total capex)
B13: Owner earnings yield = OE / mkt cap | C13: =C11/(ASSUMPTIONS!$C$6*ASSUMPTIONS!$C$7)
B16: R E V E R S E D C F — G R O W T H T H E M A R K E T I S P R I C I N G
B17: Solve g* so DCF $/sh = current price (g_term fixed).
B18: g (5yr) | C18: DCF $/sh at g | D18: value - price | F18: I M P L I E D V S B A S E
B19: -0.1 | C19: =((ASSUMPTIONS!$C$18*((ASSUMPTIONS!$C$19*(1-ASSUMPTIONS!$C$20)+ASSUMPTIONS!$C$21-ASSUMPTIONS!$C$22)-ASSUMPTIONS!$C$23*B19/(1+B19))*((1+B19)/(1+DCF!$C$11))*(1-((1+B19)/(1+DCF!$C$11))^5)/(1-((1+B19)/(1+DCF!$C$11))))+((((IF(DCF!$C$11<=ASSUMPTIONS!$C$43,0,(ASSUMPTIONS!$C$18*(1+B19)^5*((ASSUMPTIONS!$C$19*(1-ASSUMPTIONS!$C$20)+ASSUMPTIONS!$C$21-ASSUMPTIONS!$C$22)-ASSUMPTIONS!$C$23*B19/(1+B19)))*(1+ASSUMPTIONS!$C$43)/(DCF!$C$11-ASSUMPTIONS!$C$43)))+((ASSUMPTIONS!$C$18*(1+B19)^5*(ASSUMPTIONS!$C$19+ASSUMPTIONS!$C$21))*ASSUMPTIONS!$C$60))/2)/(1+DCF!$C$11)^5)-DCF!$C$12)/ASSUMPTIONS!$C$7 | D19: =C19-ASSUMPTIONS!$C$6 | F19: Implied g* (market) | G19: =IFERROR(INDEX(B19:B39,MATCH(ASSUMPTIONS!$C$6,C19:C39,1))+(ASSUMPTIONS!$C$6-INDEX(C19:C39,MATCH(ASSUMPTIONS!$C$6,C19:C39,1)))*(INDEX(B19:B39,MATCH(ASSUMPTIONS!$C$6,C19:C39,1)+1)-INDEX(B19:B39,MATCH(ASSUMPTIONS!$C$6,C19:C39,1)))/(INDEX(C19:C39,MATCH(ASSUMPTIONS!$C$6,C19:C39,1)+1)-INDEX(C19:C39,MATCH(ASSUMPTIONS!$C$6,C19:C39,1))),IF(ASSUMPTIONS!$C$6<INDEX(C19:C39,1),B19,B39))
B20: -0.08 | C20: =((ASSUMPTIONS!$C$18*((ASSUMPTIONS!$C$19*(1-ASSUMPTIONS!$C$20)+ASSUMPTIONS!$C$21-ASSUMPTIONS!$C$22)-ASSUMPTIONS!$C$23*B20/(1+B20))*((1+B20)/(1+DCF!$C$11))*(1-((1+B20)/(1+DCF!$C$11))^5)/(1-((1+B20)/(1+DCF!$C$11))))+((((IF(DCF!$C$11<=ASSUMPTIONS!$C$43,0,(ASSUMPTIONS!$C$18*(1+B20)^5*((ASSUMPTIONS!$C$19*(1-ASSUMPTIONS!$C$20)+ASSUMPTIONS!$C$21-ASSUMPTIONS!$C$22)-ASSUMPTIONS!$C$23*B20/(1+B20)))*(1+ASSUMPTIONS!$C$43)/(DCF!$C$11-ASSUMPTIONS!$C$43)))+((ASSUMPTIONS!$C$18*(1+B20)^5*(ASSUMPTIONS!$C$19+ASSUMPTIONS!$C$21))*ASSUMPTIONS!$C$60))/2)/(1+DCF!$C$11)^5)-DCF!$C$12)/ASSUMPTIONS!$C$7 | D20: =C20-ASSUMPTIONS!$C$6 | F20: Base-case g (yr1) | G20: =ASSUMPTIONS!$C$38
B21: -0.06 | C21: =((ASSUMPTIONS!$C$18*((ASSUMPTIONS!$C$19*(1-ASSUMPTIONS!$C$20)+ASSUMPTIONS!$C$21-ASSUMPTIONS!$C$22)-ASSUMPTIONS!$C$23*B21/(1+B21))*((1+B21)/(1+DCF!$C$11))*(1-((1+B21)/(1+DCF!$C$11))^5)/(1-((1+B21)/(1+DCF!$C$11))))+((((IF(DCF!$C$11<=ASSUMPTIONS!$C$43,0,(ASSUMPTIONS!$C$18*(1+B21)^5*((ASSUMPTIONS!$C$19*(1-ASSUMPTIONS!$C$20)+ASSUMPTIONS!$C$21-ASSUMPTIONS!$C$22)-ASSUMPTIONS!$C$23*B21/(1+B21)))*(1+ASSUMPTIONS!$C$43)/(DCF!$C$11-ASSUMPTIONS!$C$43)))+((ASSUMPTIONS!$C$18*(1+B21)^5*(ASSUMPTIONS!$C$19+ASSUMPTIONS!$C$21))*ASSUMPTIONS!$C$60))/2)/(1+DCF!$C$11)^5)-DCF!$C$12)/ASSUMPTIONS!$C$7 | D21: =C21-ASSUMPTIONS!$C$6 | F21: Market - base (gap) | G21: =G19-G20
B22: -0.04 | C22: =((ASSUMPTIONS!$C$18*((ASSUMPTIONS!$C$19*(1-ASSUMPTIONS!$C$20)+ASSUMPTIONS!$C$21-ASSUMPTIONS!$C$22)-ASSUMPTIONS!$C$23*B22/(1+B22))*((1+B22)/(1+DCF!$C$11))*(1-((1+B22)/(1+DCF!$C$11))^5)/(1-((1+B22)/(1+DCF!$C$11))))+((((IF(DCF!$C$11<=ASSUMPTIONS!$C$43,0,(ASSUMPTIONS!$C$18*(1+B22)^5*((ASSUMPTIONS!$C$19*(1-ASSUMPTIONS!$C$20)+ASSUMPTIONS!$C$21-ASSUMPTIONS!$C$22)-ASSUMPTIONS!$C$23*B22/(1+B22)))*(1+ASSUMPTIONS!$C$43)/(DCF!$C$11-ASSUMPTIONS!$C$43)))+((ASSUMPTIONS!$C$18*(1+B22)^5*(ASSUMPTIONS!$C$19+ASSUMPTIONS!$C$21))*ASSUMPTIONS!$C$60))/2)/(1+DCF!$C$11)^5)-DCF!$C$12)/ASSUMPTIONS!$C$7 | D22: =C22-ASSUMPTIONS!$C$6 | F22: Read | G22: =IF(G19<G20,"Market pricing LESS growth than base → cheap","Market pricing MORE growth → rich")
B23: -0.02 | C23: =((ASSUMPTIONS!$C$18*((ASSUMPTIONS!$C$19*(1-ASSUMPTIONS!$C$20)+ASSUMPTIONS!$C$21-ASSUMPTIONS!$C$22)-ASSUMPTIONS!$C$23*B23/(1+B23))*((1+B23)/(1+DCF!$C$11))*(1-((1+B23)/(1+DCF!$C$11))^5)/(1-((1+B23)/(1+DCF!$C$11))))+((((IF(DCF!$C$11<=ASSUMPTIONS!$C$43,0,(ASSUMPTIONS!$C$18*(1+B23)^5*((ASSUMPTIONS!$C$19*(1-ASSUMPTIONS!$C$20)+ASSUMPTIONS!$C$21-ASSUMPTIONS!$C$22)-ASSUMPTIONS!$C$23*B23/(1+B23)))*(1+ASSUMPTIONS!$C$43)/(DCF!$C$11-ASSUMPTIONS!$C$43)))+((ASSUMPTIONS!$C$18*(1+B23)^5*(ASSUMPTIONS!$C$19+ASSUMPTIONS!$C$21))*ASSUMPTIONS!$C$60))/2)/(1+DCF!$C$11)^5)-DCF!$C$12)/ASSUMPTIONS!$C$7 | D23: =C23-ASSUMPTIONS!$C$6
B24: 0 | C24: =((ASSUMPTIONS!$C$18*((ASSUMPTIONS!$C$19*(1-ASSUMPTIONS!$C$20)+ASSUMPTIONS!$C$21-ASSUMPTIONS!$C$22)-ASSUMPTIONS!$C$23*B24/(1+B24))*((1+B24)/(1+DCF!$C$11))*(1-((1+B24)/(1+DCF!$C$11))^5)/(1-((1+B24)/(1+DCF!$C$11))))+((((IF(DCF!$C$11<=ASSUMPTIONS!$C$43,0,(ASSUMPTIONS!$C$18*(1+B24)^5*((ASSUMPTIONS!$C$19*(1-ASSUMPTIONS!$C$20)+ASSUMPTIONS!$C$21-ASSUMPTIONS!$C$22)-ASSUMPTIONS!$C$23*B24/(1+B24)))*(1+ASSUMPTIONS!$C$43)/(DCF!$C$11-ASSUMPTIONS!$C$43)))+((ASSUMPTIONS!$C$18*(1+B24)^5*(ASSUMPTIONS!$C$19+ASSUMPTIONS!$C$21))*ASSUMPTIONS!$C$60))/2)/(1+DCF!$C$11)^5)-DCF!$C$12)/ASSUMPTIONS!$C$7 | D24: =C24-ASSUMPTIONS!$C$6
B25: 0.02 | C25: =((ASSUMPTIONS!$C$18*((ASSUMPTIONS!$C$19*(1-ASSUMPTIONS!$C$20)+ASSUMPTIONS!$C$21-ASSUMPTIONS!$C$22)-ASSUMPTIONS!$C$23*B25/(1+B25))*((1+B25)/(1+DCF!$C$11))*(1-((1+B25)/(1+DCF!$C$11))^5)/(1-((1+B25)/(1+DCF!$C$11))))+((((IF(DCF!$C$11<=ASSUMPTIONS!$C$43,0,(ASSUMPTIONS!$C$18*(1+B25)^5*((ASSUMPTIONS!$C$19*(1-ASSUMPTIONS!$C$20)+ASSUMPTIONS!$C$21-ASSUMPTIONS!$C$22)-ASSUMPTIONS!$C$23*B25/(1+B25)))*(1+ASSUMPTIONS!$C$43)/(DCF!$C$11-ASSUMPTIONS!$C$43)))+((ASSUMPTIONS!$C$18*(1+B25)^5*(ASSUMPTIONS!$C$19+ASSUMPTIONS!$C$21))*ASSUMPTIONS!$C$60))/2)/(1+DCF!$C$11)^5)-DCF!$C$12)/ASSUMPTIONS!$C$7 | D25: =C25-ASSUMPTIONS!$C$6
B26: 0.04 | C26: =((ASSUMPTIONS!$C$18*((ASSUMPTIONS!$C$19*(1-ASSUMPTIONS!$C$20)+ASSUMPTIONS!$C$21-ASSUMPTIONS!$C$22)-ASSUMPTIONS!$C$23*B26/(1+B26))*((1+B26)/(1+DCF!$C$11))*(1-((1+B26)/(1+DCF!$C$11))^5)/(1-((1+B26)/(1+DCF!$C$11))))+((((IF(DCF!$C$11<=ASSUMPTIONS!$C$43,0,(ASSUMPTIONS!$C$18*(1+B26)^5*((ASSUMPTIONS!$C$19*(1-ASSUMPTIONS!$C$20)+ASSUMPTIONS!$C$21-ASSUMPTIONS!$C$22)-ASSUMPTIONS!$C$23*B26/(1+B26)))*(1+ASSUMPTIONS!$C$43)/(DCF!$C$11-ASSUMPTIONS!$C$43)))+((ASSUMPTIONS!$C$18*(1+B26)^5*(ASSUMPTIONS!$C$19+ASSUMPTIONS!$C$21))*ASSUMPTIONS!$C$60))/2)/(1+DCF!$C$11)^5)-DCF!$C$12)/ASSUMPTIONS!$C$7 | D26: =C26-ASSUMPTIONS!$C$6
B27: 0.06 | C27: =((ASSUMPTIONS!$C$18*((ASSUMPTIONS!$C$19*(1-ASSUMPTIONS!$C$20)+ASSUMPTIONS!$C$21-ASSUMPTIONS!$C$22)-ASSUMPTIONS!$C$23*B27/(1+B27))*((1+B27)/(1+DCF!$C$11))*(1-((1+B27)/(1+DCF!$C$11))^5)/(1-((1+B27)/(1+DCF!$C$11))))+((((IF(DCF!$C$11<=ASSUMPTIONS!$C$43,0,(ASSUMPTIONS!$C$18*(1+B27)^5*((ASSUMPTIONS!$C$19*(1-ASSUMPTIONS!$C$20)+ASSUMPTIONS!$C$21-ASSUMPTIONS!$C$22)-ASSUMPTIONS!$C$23*B27/(1+B27)))*(1+ASSUMPTIONS!$C$43)/(DCF!$C$11-ASSUMPTIONS!$C$43)))+((ASSUMPTIONS!$C$18*(1+B27)^5*(ASSUMPTIONS!$C$19+ASSUMPTIONS!$C$21))*ASSUMPTIONS!$C$60))/2)/(1+DCF!$C$11)^5)-DCF!$C$12)/ASSUMPTIONS!$C$7 | D27: =C27-ASSUMPTIONS!$C$6
B28: 0.08 | C28: =((ASSUMPTIONS!$C$18*((ASSUMPTIONS!$C$19*(1-ASSUMPTIONS!$C$20)+ASSUMPTIONS!$C$21-ASSUMPTIONS!$C$22)-ASSUMPTIONS!$C$23*B28/(1+B28))*((1+B28)/(1+DCF!$C$11))*(1-((1+B28)/(1+DCF!$C$11))^5)/(1-((1+B28)/(1+DCF!$C$11))))+((((IF(DCF!$C$11<=ASSUMPTIONS!$C$43,0,(ASSUMPTIONS!$C$18*(1+B28)^5*((ASSUMPTIONS!$C$19*(1-ASSUMPTIONS!$C$20)+ASSUMPTIONS!$C$21-ASSUMPTIONS!$C$22)-ASSUMPTIONS!$C$23*B28/(1+B28)))*(1+ASSUMPTIONS!$C$43)/(DCF!$C$11-ASSUMPTIONS!$C$43)))+((ASSUMPTIONS!$C$18*(1+B28)^5*(ASSUMPTIONS!$C$19+ASSUMPTIONS!$C$21))*ASSUMPTIONS!$C$60))/2)/(1+DCF!$C$11)^5)-DCF!$C$12)/ASSUMPTIONS!$C$7 | D28: =C28-ASSUMPTIONS!$C$6
B29: 0.1 | C29: =((ASSUMPTIONS!$C$18*((ASSUMPTIONS!$C$19*(1-ASSUMPTIONS!$C$20)+ASSUMPTIONS!$C$21-ASSUMPTIONS!$C$22)-ASSUMPTIONS!$C$23*B29/(1+B29))*((1+B29)/(1+DCF!$C$11))*(1-((1+B29)/(1+DCF!$C$11))^5)/(1-((1+B29)/(1+DCF!$C$11))))+((((IF(DCF!$C$11<=ASSUMPTIONS!$C$43,0,(ASSUMPTIONS!$C$18*(1+B29)^5*((ASSUMPTIONS!$C$19*(1-ASSUMPTIONS!$C$20)+ASSUMPTIONS!$C$21-ASSUMPTIONS!$C$22)-ASSUMPTIONS!$C$23*B29/(1+B29)))*(1+ASSUMPTIONS!$C$43)/(DCF!$C$11-ASSUMPTIONS!$C$43)))+((ASSUMPTIONS!$C$18*(1+B29)^5*(ASSUMPTIONS!$C$19+ASSUMPTIONS!$C$21))*ASSUMPTIONS!$C$60))/2)/(1+DCF!$C$11)^5)-DCF!$C$12)/ASSUMPTIONS!$C$7 | D29: =C29-ASSUMPTIONS!$C$6
B30: 0.12 | C30: =((ASSUMPTIONS!$C$18*((ASSUMPTIONS!$C$19*(1-ASSUMPTIONS!$C$20)+ASSUMPTIONS!$C$21-ASSUMPTIONS!$C$22)-ASSUMPTIONS!$C$23*B30/(1+B30))*((1+B30)/(1+DCF!$C$11))*(1-((1+B30)/(1+DCF!$C$11))^5)/(1-((1+B30)/(1+DCF!$C$11))))+((((IF(DCF!$C$11<=ASSUMPTIONS!$C$43,0,(ASSUMPTIONS!$C$18*(1+B30)^5*((ASSUMPTIONS!$C$19*(1-ASSUMPTIONS!$C$20)+ASSUMPTIONS!$C$21-ASSUMPTIONS!$C$22)-ASSUMPTIONS!$C$23*B30/(1+B30)))*(1+ASSUMPTIONS!$C$43)/(DCF!$C$11-ASSUMPTIONS!$C$43)))+((ASSUMPTIONS!$C$18*(1+B30)^5*(ASSUMPTIONS!$C$19+ASSUMPTIONS!$C$21))*ASSUMPTIONS!$C$60))/2)/(1+DCF!$C$11)^5)-DCF!$C$12)/ASSUMPTIONS!$C$7 | D30: =C30-ASSUMPTIONS!$C$6
B31: 0.14 | C31: =((ASSUMPTIONS!$C$18*((ASSUMPTIONS!$C$19*(1-ASSUMPTIONS!$C$20)+ASSUMPTIONS!$C$21-ASSUMPTIONS!$C$22)-ASSUMPTIONS!$C$23*B31/(1+B31))*((1+B31)/(1+DCF!$C$11))*(1-((1+B31)/(1+DCF!$C$11))^5)/(1-((1+B31)/(1+DCF!$C$11))))+((((IF(DCF!$C$11<=ASSUMPTIONS!$C$43,0,(ASSUMPTIONS!$C$18*(1+B31)^5*((ASSUMPTIONS!$C$19*(1-ASSUMPTIONS!$C$20)+ASSUMPTIONS!$C$21-ASSUMPTIONS!$C$22)-ASSUMPTIONS!$C$23*B31/(1+B31)))*(1+ASSUMPTIONS!$C$43)/(DCF!$C$11-ASSUMPTIONS!$C$43)))+((ASSUMPTIONS!$C$18*(1+B31)^5*(ASSUMPTIONS!$C$19+ASSUMPTIONS!$C$21))*ASSUMPTIONS!$C$60))/2)/(1+DCF!$C$11)^5)-DCF!$C$12)/ASSUMPTIONS!$C$7 | D31: =C31-ASSUMPTIONS!$C$6
B32: 0.16 | C32: =((ASSUMPTIONS!$C$18*((ASSUMPTIONS!$C$19*(1-ASSUMPTIONS!$C$20)+ASSUMPTIONS!$C$21-ASSUMPTIONS!$C$22)-ASSUMPTIONS!$C$23*B32/(1+B32))*((1+B32)/(1+DCF!$C$11))*(1-((1+B32)/(1+DCF!$C$11))^5)/(1-((1+B32)/(1+DCF!$C$11))))+((((IF(DCF!$C$11<=ASSUMPTIONS!$C$43,0,(ASSUMPTIONS!$C$18*(1+B32)^5*((ASSUMPTIONS!$C$19*(1-ASSUMPTIONS!$C$20)+ASSUMPTIONS!$C$21-ASSUMPTIONS!$C$22)-ASSUMPTIONS!$C$23*B32/(1+B32)))*(1+ASSUMPTIONS!$C$43)/(DCF!$C$11-ASSUMPTIONS!$C$43)))+((ASSUMPTIONS!$C$18*(1+B32)^5*(ASSUMPTIONS!$C$19+ASSUMPTIONS!$C$21))*ASSUMPTIONS!$C$60))/2)/(1+DCF!$C$11)^5)-DCF!$C$12)/ASSUMPTIONS!$C$7 | D32: =C32-ASSUMPTIONS!$C$6
B33: 0.18 | C33: =((ASSUMPTIONS!$C$18*((ASSUMPTIONS!$C$19*(1-ASSUMPTIONS!$C$20)+ASSUMPTIONS!$C$21-ASSUMPTIONS!$C$22)-ASSUMPTIONS!$C$23*B33/(1+B33))*((1+B33)/(1+DCF!$C$11))*(1-((1+B33)/(1+DCF!$C$11))^5)/(1-((1+B33)/(1+DCF!$C$11))))+((((IF(DCF!$C$11<=ASSUMPTIONS!$C$43,0,(ASSUMPTIONS!$C$18*(1+B33)^5*((ASSUMPTIONS!$C$19*(1-ASSUMPTIONS!$C$20)+ASSUMPTIONS!$C$21-ASSUMPTIONS!$C$22)-ASSUMPTIONS!$C$23*B33/(1+B33)))*(1+ASSUMPTIONS!$C$43)/(DCF!$C$11-ASSUMPTIONS!$C$43)))+((ASSUMPTIONS!$C$18*(1+B33)^5*(ASSUMPTIONS!$C$19+ASSUMPTIONS!$C$21))*ASSUMPTIONS!$C$60))/2)/(1+DCF!$C$11)^5)-DCF!$C$12)/ASSUMPTIONS!$C$7 | D33: =C33-ASSUMPTIONS!$C$6
B34: 0.2 | C34: =((ASSUMPTIONS!$C$18*((ASSUMPTIONS!$C$19*(1-ASSUMPTIONS!$C$20)+ASSUMPTIONS!$C$21-ASSUMPTIONS!$C$22)-ASSUMPTIONS!$C$23*B34/(1+B34))*((1+B34)/(1+DCF!$C$11))*(1-((1+B34)/(1+DCF!$C$11))^5)/(1-((1+B34)/(1+DCF!$C$11))))+((((IF(DCF!$C$11<=ASSUMPTIONS!$C$43,0,(ASSUMPTIONS!$C$18*(1+B34)^5*((ASSUMPTIONS!$C$19*(1-ASSUMPTIONS!$C$20)+ASSUMPTIONS!$C$21-ASSUMPTIONS!$C$22)-ASSUMPTIONS!$C$23*B34/(1+B34)))*(1+ASSUMPTIONS!$C$43)/(DCF!$C$11-ASSUMPTIONS!$C$43)))+((ASSUMPTIONS!$C$18*(1+B34)^5*(ASSUMPTIONS!$C$19+ASSUMPTIONS!$C$21))*ASSUMPTIONS!$C$60))/2)/(1+DCF!$C$11)^5)-DCF!$C$12)/ASSUMPTIONS!$C$7 | D34: =C34-ASSUMPTIONS!$C$6
... B39: 0.3 | C39: =((ASSUMPTIONS!$C$18*((ASSUMPTIONS!$C$19*(1-ASSUMPTIONS!$C$20)+ASSUMPTIONS!$C$21-ASSUMPTIONS!$C$22)-ASSUMPTIONS!$C$23*B39/(1+B39))*((1+B39)/(1+DCF!$C$11))*(1-((1+B39)/(1+DCF!$C$11))^5)/(1-((1+B39)/(1+DCF!$C$11))))+((((IF(DCF!$C$11<=ASSUMPTIONS!$C$43,0,(ASSUMPTIONS!$C$18*(1+B39)^5*((ASSUMPTIONS!$C$19*(1-ASSUMPTIONS!$C$20)+ASSUMPTIONS!$C$21-ASSUMPTIONS!$C$22)-ASSUMPTIONS!$C$23*B39/(1+B39)))*(1+ASSUMPTIONS!$C$43)/(DCF!$C$11-ASSUMPTIONS!$C$43)))+((ASSUMPTIONS!$C$18*(1+B39)^5*(ASSUMPTIONS!$C$19+ASSUMPTIONS!$C$21))*ASSUMPTIONS!$C$60))/2)/(1+DCF!$C$11)^5)-DCF!$C$12)/ASSUMPTIONS!$C$7 | D39: =C39-ASSUMPTIONS!$C$6

Sheet QUALITY
A1: QUALITY & SAFETY
A2: ROIC vs WACC, Piotroski F-Score, Altman Z, Beneish M.
A3: EQUITY VALUATION COCKPIT • APEX TECHNOLOGIES (SAMPLE) • APEX
B5: R O I C V S W A C C
B6: NOPAT (current) | C6: =(ASSUMPTIONS!$C$18*ASSUMPTIONS!$C$19*(1-ASSUMPTIONS!$C$20))
B7: Invested capital = Debt+Equity-Cash | C7: =ASSUMPTIONS!$C$28+ASSUMPTIONS!$C$30-ASSUMPTIONS!$C$29
B8: ROIC = NOPAT / invested capital | C8: =IF(C7=0,NA(),C6/C7)
B9: WACC | C9: =DCF!$C$11
B10: Spread = ROIC - WACC | C10: =C8-C9
B11: Verdict | C11: =IF(C8>C9,"VALUE-CREATING","VALUE-DESTROYING")
B13: P I O T R O S K I F - S C O R E ( 0 - 9 )
B14: Criterion | C14: Pass(1/0)
B15: F1 ROA > 0 | C15: =ASSUMPTIONS!$C$75
B16: F2 CFO > 0 | C16: =ASSUMPTIONS!$C$76
B17: F3 dROA > 0 vs prior | C17: =ASSUMPTIONS!$C$77
B18: F4 CFO > Net income | C18: =ASSUMPTIONS!$C$78
B19: F5 Lower LT-debt ratio | C19: =ASSUMPTIONS!$C$79
B20: F6 Higher current ratio | C20: =ASSUMPTIONS!$C$80
B21: F7 No new shares issued | C21: =ASSUMPTIONS!$C$81
B22: F8 Higher gross margin | C22: =ASSUMPTIONS!$C$82
B23: F9 Higher asset turnover | C23: =ASSUMPTIONS!$C$83
B24: F-Score total | C24: =SUM(C15:C23)
B26: A L T M A N Z - S C O R E ( M A N U F A C T U R I N G )
B27: A = (CA-CL)/TA | C27: =(ASSUMPTIONS!$C$32-ASSUMPTIONS!$C$33)/ASSUMPTIONS!$C$31
B28: B = RetainedEarnings/TA | C28: =ASSUMPTIONS!$C$34/ASSUMPTIONS!$C$31
B29: C = EBIT/TA | C29: =(ASSUMPTIONS!$C$18*ASSUMPTIONS!$C$19)/ASSUMPTIONS!$C$31
B30: D = MktCapEquity/TotalLiab | C30: =(ASSUMPTIONS!$C$6*ASSUMPTIONS!$C$7)/ASSUMPTIONS!$C$35
B31: E = Revenue/TA | C31: =ASSUMPTIONS!$C$18/ASSUMPTIONS!$C$31
B32: Z = 1.2A+1.4B+3.3C+0.6D+1.0E | C32: =1.2*C27+1.4*C28+3.3*C29+0.6*C30+1.0*C31
B33: Zone | C33: =IF(C32>2.99,"SAFE",IF(C32>=1.81,"GREY","DISTRESS"))
B35: B E N E I S H M - S C O R E
B36: Ratio | C36: Input | D36: Coef
B37: DSRI | C37: =ASSUMPTIONS!$C$86 | D37: 0.92
B38: GMI | C38: =ASSUMPTIONS!$C$87 | D38: 0.528
B39: AQI | C39: =ASSUMPTIONS!$C$88 | D39: 0.404
B40: SGI | C40: =ASSUMPTIONS!$C$89 | D40: 0.892
B41: DEPI | C41: =ASSUMPTIONS!$C$90 | D41: 0.115
B42: SGAI | C42: =ASSUMPTIONS!$C$91 | D42: -0.172
B43: TATA | C43: =ASSUMPTIONS!$C$92 | D43: 4.679
B44: LVGI | C44: =ASSUMPTIONS!$C$93 | D44: -0.327
...

Sheet TIMING
A1: TIMING & ENTRY
A2: Fibonacci ladder, moving averages, RSI, 52-week position, MoS bands, DCA planner.
A3: EQUITY VALUATION COCKPIT • APEX TECHNOLOGIES (SAMPLE) • APEX
B5: F I B O N A C C I R E T R A C E M E N T L A D D E R | F5: R S I & 5 2 - W E E K P O S I T I O N
B6: Swing high H | C6: =ASSUMPTIONS!$C$10 | F6: RSI(14) | G6: =ASSUMPTIONS!$C$14
B7: Swing low L | C7: =ASSUMPTIONS!$C$11 | F7: RSI state | G7: =IF(ASSUMPTIONS!$C$14<30,"OVERSOLD",IF(ASSUMPTIONS!$C$14>70,"OVERBOUGHT","NEUTRAL"))
B8: Range R = H - L | C8: =C6-C7 | F8: 52w range position | G8: =(ASSUMPTIONS!$C$6-ASSUMPTIONS!$C$9)/(ASSUMPTIONS!$C$8-ASSUMPTIONS!$C$9)
F9: 0%=low 100%=high
B10: Level | C10: Price | D10: vs price
B11: 0.000 (H) | C11: =C6-C8*0.0 | D11: =C11-ASSUMPTIONS!$C$6
B12: 0.236 | C12: =C6-C8*0.236 | D12: =C12-ASSUMPTIONS!$C$6
B13: 0.382 | C13: =C6-C8*0.382 | D13: =C13-ASSUMPTIONS!$C$6
B14: 0.500 | C14: =C6-C8*0.5 | D14: =C14-ASSUMPTIONS!$C$6
B15: 0.618 | C15: =C6-C8*0.618 | D15: =C15-ASSUMPTIONS!$C$6
B16: 0.786 | C16: =C6-C8*0.786 | D16: =C16-ASSUMPTIONS!$C$6
B17: 1.000 (L) | C17: =C6-C8*1.0 | D17: =C17-ASSUMPTIONS!$C$6
B18: 1.272 ext | C18: =C7-C8*(1.272-1) | D18: =C18-ASSUMPTIONS!$C$6
B19: 1.618 ext | C19: =C7-C8*(1.618-1) | D19: =C19-ASSUMPTIONS!$C$6
B21: Nearest Fib support < price | C21: =_xlfn.MAXIFS(C11:C19,C11:C19,"<="&ASSUMPTIONS!$C$6)
B23: M O V I N G A V E R A G E S & T R E N D
B24: Price | C24: =ASSUMPTIONS!$C$6
B25: 50-day MA | C25: =ASSUMPTIONS!$C$12
B26: 200-day MA | C26: =ASSUMPTIONS!$C$13
B27: Cross signal | C27: =IF(ASSUMPTIONS!$C$12>ASSUMPTIONS!$C$13,"GOLDEN CROSS","DEATH CROSS")
B28: Trend vs MAs | C28: =IF(AND(ASSUMPTIONS!$C$6>ASSUMPTIONS!$C$12,ASSUMPTIONS!$C$6>ASSUMPTIONS!$C$13),"UPTREND",IF(AND(ASSUMPTIONS!$C$6<ASSUMPTIONS!$C$12,ASSUMPTIONS!$C$6<ASSUMPTIONS!$C$13),"DOWNTREND","MIXED"))
B30: M A R G I N - O F - S A F E T Y B A N D S | F30: D C A 4 - T R A N C H E P L A N N E R
B31: MoS | C31: Buy price | F31: Tranche | G31: Buy price | H31: Weight
B32: 15% MoS | C32: =DASHBOARD!$C$8*(1-0.15) | F32: T1 @ market | G32: =ASSUMPTIONS!$C$6 | H32: 0.4
B33: 30% MoS | C33: =DASHBOARD!$C$8*(1-0.3) | F33: T2 @ Fib .382 | G33: =MIN((C6-C8*0.382),DASHBOARD!$C$8*(1-0.10)) | H33: 0.3
B34: 50% MoS | C34: =DASHBOARD!$C$8*(1-0.5) | F34: T3 @ Fib .500 | G34: =MIN((C6-C8*0.5),DASHBOARD!$C$8*(1-0.20)) | H34: 0.2
F35: T4 @ Fib .618 | G35: =MIN((C6-C8*0.618),DASHBOARD!$C$8*(1-0.30)) | H35: 0.1
F36: Blended avg cost | G36: =SUMPRODUCT(G32:G35,H32:H35)
F37: Discount to FV | G37: =1-G36/DASHBOARD!$C$8

Sheet SCENARIO_MC
A1: SCENARIO & MONTE CARLO
A2: Bull/Base/Bear DCF, 2000-trial Monte Carlo, percentiles, and Kelly sizing.
A3: EQUITY VALUATION COCKPIT • APEX TECHNOLOGIES (SAMPLE) • APEX
B5: S C E N A R I O F A I R V A L U E S ( $ / S H ) | H5: M O N T E C A R L O E N G I N E — 2 0 0 0 T R I A L S | N5: M C S U M M A R Y
B6: Driver | C6: BEAR | D6: BASE | E6: BULL | H6: g | I6: WACC | J6: margin | K6: g_term | L6: FV $/sh | N6: P5 | O6: =_xlfn.PERCENTILE.INC(L7:L2006,0.05)
B7: Avg growth g | C7: =AVERAGE(ASSUMPTIONS!$C$38,ASSUMPTIONS!$C$39,ASSUMPTIONS!$C$40,ASSUMPTIONS!$C$41,ASSUMPTIONS!$C$42)-0.03 | D7: =AVERAGE(ASSUMPTIONS!$C$38,ASSUMPTIONS!$C$39,ASSUMPTIONS!$C$40,ASSUMPTIONS!$C$41,ASSUMPTIONS!$C$42) | E7: =AVERAGE(ASSUMPTIONS!$C$38,ASSUMPTIONS!$C$39,ASSUMPTIONS!$C$40,ASSUMPTIONS!$C$41,ASSUMPTIONS!$C$42)+0.03 | H7: =_xlfn.NORM.INV(RAND(),AVERAGE(ASSUMPTIONS!$C$38,ASSUMPTIONS!$C$39,ASSUMPTIONS!$C$40,ASSUMPTIONS!$C$41,ASSUMPTIONS!$C$42),ASSUMPTIONS!$C$68) | I7: =MAX(_xlfn.NORM.INV(RAND(),DCF!$C$11,ASSUMPTIONS!$C$69),K7+0.005) | J7: =_xlfn.NORM.INV(RAND(),ASSUMPTIONS!$C$19,ASSUMPTIONS!$C$70) | K7: =_xlfn.NORM.INV(RAND(),ASSUMPTIONS!$C$43,ASSUMPTIONS!$C$71) | L7: =(((ASSUMPTIONS!$C$18*J7*(1-ASSUMPTIONS!$C$20)+ASSUMPTIONS!$C$18*ASSUMPTIONS!$C$21-ASSUMPTIONS!$C$18*ASSUMPTIONS!$C$22)*(1+H7)*(1-((1+H7)/(1+I7))^5)/(I7-H7))+((ASSUMPTIONS!$C$18*J7*(1-ASSUMPTIONS!$C$20)+ASSUMPTIONS!$C$18*ASSUMPTIONS!$C$21-ASSUMPTIONS!$C$18*ASSUMPTIONS!$C$22)*(1+H7)^5*(1+K7)/(I7-K7)/(1+I7)^5)-DCF!$C$12)/ASSUMPTIONS!$C$7 | N7: P25 | O7: =_xlfn.PERCENTILE.INC(L7:L2006,0.25)
B8: EBIT margin | C8: =ASSUMPTIONS!$C$19-0.03 | D8: =ASSUMPTIONS!$C$19 | E8: =ASSUMPTIONS!$C$19+0.02 | H8: =_xlfn.NORM.INV(RAND(),AVERAGE(ASSUMPTIONS!$C$38,ASSUMPTIONS!$C$39,ASSUMPTIONS!$C$40,ASSUMPTIONS!$C$41,ASSUMPTIONS!$C$42),ASSUMPTIONS!$C$68) | I8: =MAX(_xlfn.NORM.INV(RAND(),DCF!$C$11,ASSUMPTIONS!$C$69),K8+0.005) | J8: =_xlfn.NORM.INV(RAND(),ASSUMPTIONS!$C$19,ASSUMPTIONS!$C$70) | K8: =_xlfn.NORM.INV(RAND(),ASSUMPTIONS!$C$43,ASSUMPTIONS!$C$71) | L8: =(((ASSUMPTIONS!$C$18*J8*(1-ASSUMPTIONS!$C$20)+ASSUMPTIONS!$C$18*ASSUMPTIONS!$C$21-ASSUMPTIONS!$C$18*ASSUMPTIONS!$C$22)*(1+H8)*(1-((1+H8)/(1+I8))^5)/(I8-H8))+((ASSUMPTIONS!$C$18*J8*(1-ASSUMPTIONS!$C$20)+ASSUMPTIONS!$C$18*ASSUMPTIONS!$C$21-ASSUMPTIONS!$C$18*ASSUMPTIONS!$C$22)*(1+H8)^5*(1+K8)/(I8-K8)/(1+I8)^5)-DCF!$C$12)/ASSUMPTIONS!$C$7 | N8: P50 (median) | O8: =_xlfn.PERCENTILE.INC(L7:L2006,0.50)
B9: WACC | C9: =DCF!$C$11+0.01 | D9: =DCF!$C$11 | E9: =DCF!$C$11-0.005 | H9: =_xlfn.NORM.INV(RAND(),AVERAGE(ASSUMPTIONS!$C$38,ASSUMPTIONS!$C$39,ASSUMPTIONS!$C$40,ASSUMPTIONS!$C$41,ASSUMPTIONS!$C$42),ASSUMPTIONS!$C$68) | I9: =MAX(_xlfn.NORM.INV(RAND(),DCF!$C$11,ASSUMPTIONS!$C$69),K9+0.005) | J9: =_xlfn.NORM.INV(RAND(),ASSUMPTIONS!$C$19,ASSUMPTIONS!$C$70) | K9: =_xlfn.NORM.INV(RAND(),ASSUMPTIONS!$C$43,ASSUMPTIONS!$C$71) | L9: =(((ASSUMPTIONS!$C$18*J9*(1-ASSUMPTIONS!$C$20)+ASSUMPTIONS!$C$18*ASSUMPTIONS!$C$21-ASSUMPTIONS!$C$18*ASSUMPTIONS!$C$22)*(1+H9)*(1-((1+H9)/(1+I9))^5)/(I9-H9))+((ASSUMPTIONS!$C$18*J9*(1-ASSUMPTIONS!$C$20)+ASSUMPTIONS!$C$18*ASSUMPTIONS!$C$21-ASSUMPTIONS!$C$18*ASSUMPTIONS!$C$22)*(1+H9)^5*(1+K9)/(I9-K9)/(1+I9)^5)-DCF!$C$12)/ASSUMPTIONS!$C$7 | N9: P75 | O9: =_xlfn.PERCENTILE.INC(L7:L2006,0.75)
B10: Exit EV/EBITDA | C10: =ASSUMPTIONS!$C$61 | D10: =ASSUMPTIONS!$C$60 | E10: =ASSUMPTIONS!$C$62 | H10: =_xlfn.NORM.INV(RAND(),AVERAGE(ASSUMPTIONS!$C$38,ASSUMPTIONS!$C$39,ASSUMPTIONS!$C$40,ASSUMPTIONS!$C$41,ASSUMPTIONS!$C$42),ASSUMPTIONS!$C$68) | I10: =MAX(_xlfn.NORM.INV(RAND(),DCF!$C$11,ASSUMPTIONS!$C$69),K10+0.005) | J10: =_xlfn.NORM.INV(RAND(),ASSUMPTIONS!$C$19,ASSUMPTIONS!$C$70) | K10: =_xlfn.NORM.INV(RAND(),ASSUMPTIONS!$C$43,ASSUMPTIONS!$C$71) | L10: =(((ASSUMPTIONS!$C$18*J10*(1-ASSUMPTIONS!$C$20)+ASSUMPTIONS!$C$18*ASSUMPTIONS!$C$21-ASSUMPTIONS!$C$18*ASSUMPTIONS!$C$22)*(1+H10)*(1-((1+H10)/(1+I10))^5)/(I10-H10))+((ASSUMPTIONS!$C$18*J10*(1-ASSUMPTIONS!$C$20)+ASSUMPTIONS!$C$18*ASSUMPTIONS!$C$21-ASSUMPTIONS!$C$18*ASSUMPTIONS!$C$22)*(1+H10)^5*(1+K10)/(I10-K10)/(1+I10)^5)-DCF!$C$12)/ASSUMPTIONS!$C$7 | N10: P95 | O10: =_xlfn.PERCENTILE.INC(L7:L2006,0.95)
H11: =_xlfn.NORM.INV(RAND(),AVERAGE(ASSUMPTIONS!$C$38,ASSUMPTIONS!$C$39,ASSUMPTIONS!$C$40,ASSUMPTIONS!$C$41,ASSUMPTIONS!$C$42),ASSUMPTIONS!$C$68) | I11: =MAX(_xlfn.NORM.INV(RAND(),DCF!$C$11,ASSUMPTIONS!$C$69),K11+0.005) | J11: =_xlfn.NORM.INV(RAND(),ASSUMPTIONS!$C$19,ASSUMPTIONS!$C$70) | K11: =_xlfn.NORM.INV(RAND(),ASSUMPTIONS!$C$43,ASSUMPTIONS!$C$71) | L11: =(((ASSUMPTIONS!$C$18*J11*(1-ASSUMPTIONS!$C$20)+ASSUMPTIONS!$C$18*ASSUMPTIONS!$C$21-ASSUMPTIONS!$C$18*ASSUMPTIONS!$C$22)*(1+H11)*(1-((1+H11)/(1+I11))^5)/(I11-H11))+((ASSUMPTIONS!$C$18*J11*(1-ASSUMPTIONS!$C$20)+ASSUMPTIONS!$C$18*ASSUMPTIONS!$C$21-ASSUMPTIONS!$C$18*ASSUMPTIONS!$C$22)*(1+H11)^5*(1+K11)/(I11-K11)/(1+I11)^5)-DCF!$C$12)/ASSUMPTIONS!$C$7 | N11: Mean | O11: =AVERAGE(L7:L2006)
B12: REVENUE ($M) | H12: =_xlfn.NORM.INV(RAND(),AVERAGE(ASSUMPTIONS!$C$38,ASSUMPTIONS!$C$39,ASSUMPTIONS!$C$40,ASSUMPTIONS!$C$41,ASSUMPTIONS!$C$42),ASSUMPTIONS!$C$68) | I12: =MAX(_xlfn.NORM.INV(RAND(),DCF!$C$11,ASSUMPTIONS!$C$69),K12+0.005) | J12: =_xlfn.NORM.INV(RAND(),ASSUMPTIONS!$C$19,ASSUMPTIONS!$C$70) | K12: =_xlfn.NORM.INV(RAND(),ASSUMPTIONS!$C$43,ASSUMPTIONS!$C$71) | L12: =(((ASSUMPTIONS!$C$18*J12*(1-ASSUMPTIONS!$C$20)+ASSUMPTIONS!$C$18*ASSUMPTIONS!$C$21-ASSUMPTIONS!$C$18*ASSUMPTIONS!$C$22)*(1+H12)*(1-((1+H12)/(1+I12))^5)/(I12-H12))+((ASSUMPTIONS!$C$18*J12*(1-ASSUMPTIONS!$C$20)+ASSUMPTIONS!$C$18*ASSUMPTIONS!$C$21-ASSUMPTIONS!$C$18*ASSUMPTIONS!$C$22)*(1+H12)^5*(1+K12)/(I12-K12)/(1+I12)^5)-DCF!$C$12)/ASSUMPTIONS!$C$7 | N12: P(FV > price) | O12: =IFERROR(COUNTIF(L7:L2006,">"&ASSUMPTIONS!$C$6)/2000,NA())
B13: Year 1 | C13: =ASSUMPTIONS!$C$18*(1+ASSUMPTIONS!$C$38-0.03) | D13: =ASSUMPTIONS!$C$18*(1+ASSUMPTIONS!$C$38) | E13: =ASSUMPTIONS!$C$18*(1+ASSUMPTIONS!$C$38+0.03) | H13: =_xlfn.NORM.INV(RAND(),AVERAGE(ASSUMPTIONS!$C$38,ASSUMPTIONS!$C$39,ASSUMPTIONS!$C$40,ASSUMPTIONS!$C$41,ASSUMPTIONS!$C$42),ASSUMPTIONS!$C$68) | I13: =MAX(_xlfn.NORM.INV(RAND(),DCF!$C$11,ASSUMPTIONS!$C$69),K13+0.005) | J13: =_xlfn.NORM.INV(RAND(),ASSUMPTIONS!$C$19,ASSUMPTIONS!$C$70) | K13: =_xlfn.NORM.INV(RAND(),ASSUMPTIONS!$C$43,ASSUMPTIONS!$C$71) | L13: =(((ASSUMPTIONS!$C$18*J13*(1-ASSUMPTIONS!$C$20)+ASSUMPTIONS!$C$18*ASSUMPTIONS!$C$21-ASSUMPTIONS!$C$18*ASSUMPTIONS!$C$22)*(1+H13)*(1-((1+H13)/(1+I13))^5)/(I13-H13))+((ASSUMPTIONS!$C$18*J13*(1-ASSUMPTIONS!$C$20)+ASSUMPTIONS!$C$18*ASSUMPTIONS!$C$21-ASSUMPTIONS!$C$18*ASSUMPTIONS!$C$22)*(1+H13)^5*(1+K13)/(I13-K13)/(1+I13)^5)-DCF!$C$12)/ASSUMPTIONS!$C$7
B14: Year 2 | C14: =C13*(1+ASSUMPTIONS!$C$39-0.03) | D14: =D13*(1+ASSUMPTIONS!$C$39) | E14: =E13*(1+ASSUMPTIONS!$C$39+0.03) | H14: =_xlfn.NORM.INV(RAND(),AVERAGE(ASSUMPTIONS!$C$38,ASSUMPTIONS!$C$39,ASSUMPTIONS!$C$40,ASSUMPTIONS!$C$41,ASSUMPTIONS!$C$42),ASSUMPTIONS!$C$68) | I14: =MAX(_xlfn.NORM.INV(RAND(),DCF!$C$11,ASSUMPTIONS!$C$69),K14+0.005) | J14: =_xlfn.NORM.INV(RAND(),ASSUMPTIONS!$C$19,ASSUMPTIONS!$C$70) | K14: =_xlfn.NORM.INV(RAND(),ASSUMPTIONS!$C$43,ASSUMPTIONS!$C$71) | L14: =(((ASSUMPTIONS!$C$18*J14*(1-ASSUMPTIONS!$C$20)+ASSUMPTIONS!$C$18*ASSUMPTIONS!$C$21-ASSUMPTIONS!$C$18*ASSUMPTIONS!$C$22)*(1+H14)*(1-((1+H14)/(1+I14))^5)/(I14-H14))+((ASSUMPTIONS!$C$18*J14*(1-ASSUMPTIONS!$C$20)+ASSUMPTIONS!$C$18*ASSUMPTIONS!$C$21-ASSUMPTIONS!$C$18*ASSUMPTIONS!$C$22)*(1+H14)^5*(1+K14)/(I14-K14)/(1+I14)^5)-DCF!$C$12)/ASSUMPTIONS!$C$7 | N14: H I S T O G R A M B I N S
B15: Year 3 | C15: =C14*(1+ASSUMPTIONS!$C$40-0.03) | D15: =D14*(1+ASSUMPTIONS!$C$40) | E15: =E14*(1+ASSUMPTIONS!$C$40+0.03) | H15: =_xlfn.NORM.INV(RAND(),AVERAGE(ASSUMPTIONS!$C$38,ASSUMPTIONS!$C$39,ASSUMPTIONS!$C$40,ASSUMPTIONS!$C$41,ASSUMPTIONS!$C$42),ASSUMPTIONS!$C$68) | I15: =MAX(_xlfn.NORM.INV(RAND(),DCF!$C$11,ASSUMPTIONS!$C$69),K15+0.005) | J15: =_xlfn.NORM.INV(RAND(),ASSUMPTIONS!$C$19,ASSUMPTIONS!$C$70) | K15: =_xlfn.NORM.INV(RAND(),ASSUMPTIONS!$C$43,ASSUMPTIONS!$C$71) | L15: =(((ASSUMPTIONS!$C$18*J15*(1-ASSUMPTIONS!$C$20)+ASSUMPTIONS!$C$18*ASSUMPTIONS!$C$21-ASSUMPTIONS!$C$18*ASSUMPTIONS!$C$22)*(1+H15)*(1-((1+H15)/(1+I15))^5)/(I15-H15))+((ASSUMPTIONS!$C$18*J15*(1-ASSUMPTIONS!$C$20)+ASSUMPTIONS!$C$18*ASSUMPTIONS!$C$21-ASSUMPTIONS!$C$18*ASSUMPTIONS!$C$22)*(1+H15)^5*(1+K15)/(I15-K15)/(1+I15)^5)-DCF!$C$12)/ASSUMPTIONS!$C$7 | N15: Bin upper | O15: Count
B16: Year 4 | C16: =C15*(1+ASSUMPTIONS!$C$41-0.03) | D16: =D15*(1+ASSUMPTIONS!$C$41) | E16: =E15*(1+ASSUMPTIONS!$C$41+0.03) | H16: =_xlfn.NORM.INV(RAND(),AVERAGE(ASSUMPTIONS!$C$38,ASSUMPTIONS!$C$39,ASSUMPTIONS!$C$40,ASSUMPTIONS!$C$41,ASSUMPTIONS!$C$42),ASSUMPTIONS!$C$68) | I16: =MAX(_xlfn.NORM.INV(RAND(),DCF!$C$11,ASSUMPTIONS!$C$69),K16+0.005) | J16: =_xlfn.NORM.INV(RAND(),ASSUMPTIONS!$C$19,ASSUMPTIONS!$C$70) | K16: =_xlfn.NORM.INV(RAND(),ASSUMPTIONS!$C$43,ASSUMPTIONS!$C$71) | L16: =(((ASSUMPTIONS!$C$18*J16*(1-ASSUMPTIONS!$C$20)+ASSUMPTIONS!$C$18*ASSUMPTIONS!$C$21-ASSUMPTIONS!$C$18*ASSUMPTIONS!$C$22)*(1+H16)*(1-((1+H16)/(1+I16))^5)/(I16-H16))+((ASSUMPTIONS!$C$18*J16*(1-ASSUMPTIONS!$C$20)+ASSUMPTIONS!$C$18*ASSUMPTIONS!$C$21-ASSUMPTIONS!$C$18*ASSUMPTIONS!$C$22)*(1+H16)^5*(1+K16)/(I16-K16)/(1+I16)^5)-DCF!$C$12)/ASSUMPTIONS!$C$7 | N16: =MIN(L7:L2006)+(0.08333333333333333)*(MAX(L7:L2006)-MIN(L7:L2006)) | O16: =COUNTIF(L7:L2006,"<="&N16)
B17: Year 5 | C17: =C16*(1+ASSUMPTIONS!$C$42-0.03) | D17: =D16*(1+ASSUMPTIONS!$C$42) | E17: =E16*(1+ASSUMPTIONS!$C$42+0.03) | H17: =_xlfn.NORM.INV(RAND(),AVERAGE(ASSUMPTIONS!$C$38,ASSUMPTIONS!$C$39,ASSUMPTIONS!$C$40,ASSUMPTIONS!$C$41,ASSUMPTIONS!$C$42),ASSUMPTIONS!$C$68) | I17: =MAX(_xlfn.NORM.INV(RAND(),DCF!$C$11,ASSUMPTIONS!$C$69),K17+0.005) | J17: =_xlfn.NORM.INV(RAND(),ASSUMPTIONS!$C$19,ASSUMPTIONS!$C$70) | K17: =_xlfn.NORM.INV(RAND(),ASSUMPTIONS!$C$43,ASSUMPTIONS!$C$71) | L17: =(((ASSUMPTIONS!$C$18*J17*(1-ASSUMPTIONS!$C$20)+ASSUMPTIONS!$C$18*ASSUMPTIONS!$C$21-ASSUMPTIONS!$C$18*ASSUMPTIONS!$C$22)*(1+H17)*(1-((1+H17)/(1+I17))^5)/(I17-H17))+((ASSUMPTIONS!$C$18*J17*(1-ASSUMPTIONS!$C$20)+ASSUMPTIONS!$C$18*ASSUMPTIONS!$C$21-ASSUMPTIONS!$C$18*ASSUMPTIONS!$C$22)*(1+H17)^5*(1+K17)/(I17-K17)/(1+I17)^5)-DCF!$C$12)/ASSUMPTIONS!$C$7 | N17: =MIN(L7:L2006)+(0.16666666666666666)*(MAX(L7:L2006)-MIN(L7:L2006)) | O17: =COUNTIFS(L7:L2006,">"&N16,L7:L2006,"<="&N17)
H18: =_xlfn.NORM.INV(RAND(),AVERAGE(ASSUMPTIONS!$C$38,ASSUMPTIONS!$C$39,ASSUMPTIONS!$C$40,ASSUMPTIONS!$C$41,ASSUMPTIONS!$C$42),ASSUMPTIONS!$C$68) | I18: =MAX(_xlfn.NORM.INV(RAND(),DCF!$C$11,ASSUMPTIONS!$C$69),K18+0.005) | J18: =_xlfn.NORM.INV(RAND(),ASSUMPTIONS!$C$19,ASSUMPTIONS!$C$70) | K18: =_xlfn.NORM.INV(RAND(),ASSUMPTIONS!$C$43,ASSUMPTIONS!$C$71) | L18: =(((ASSUMPTIONS!$C$18*J18*(1-ASSUMPTIONS!$C$20)+ASSUMPTIONS!$C$18*ASSUMPTIONS!$C$21-ASSUMPTIONS!$C$18*ASSUMPTIONS!$C$22)*(1+H18)*(1-((1+H18)/(1+I18))^5)/(I18-H18))+((ASSUMPTIONS!$C$18*J18*(1-ASSUMPTIONS!$C$20)+ASSUMPTIONS!$C$18*ASSUMPTIONS!$C$21-ASSUMPTIONS!$C$18*ASSUMPTIONS!$C$22)*(1+H18)^5*(1+K18)/(I18-K18)/(1+I18)^5)-DCF!$C$12)/ASSUMPTIONS!$C$7 | N18: =MIN(L7:L2006)+(0.25)*(MAX(L7:L2006)-MIN(L7:L2006)) | O18: =COUNTIFS(L7:L2006,">"&N17,L7:L2006,"<="&N18)
B19: FCFF ($M) | H19: =_xlfn.NORM.INV(RAND(),AVERAGE(ASSUMPTIONS!$C$38,ASSUMPTIONS!$C$39,ASSUMPTIONS!$C$40,ASSUMPTIONS!$C$41,ASSUMPTIONS!$C$42),ASSUMPTIONS!$C$68) | I19: =MAX(_xlfn.NORM.INV(RAND(),DCF!$C$11,ASSUMPTIONS!$C$69),K19+0.005) | J19: =_xlfn.NORM.INV(RAND(),ASSUMPTIONS!$C$19,ASSUMPTIONS!$C$70) | K19: =_xlfn.NORM.INV(RAND(),ASSUMPTIONS!$C$43,ASSUMPTIONS!$C$71) | L19: =(((ASSUMPTIONS!$C$18*J19*(1-ASSUMPTIONS!$C$20)+ASSUMPTIONS!$C$18*ASSUMPTIONS!$C$21-ASSUMPTIONS!$C$18*ASSUMPTIONS!$C$22)*(1+H19)*(1-((1+H19)/(1+I19))^5)/(I19-H19))+((ASSUMPTIONS!$C$18*J19*(1-ASSUMPTIONS!$C$20)+ASSUMPTIONS!$C$18*ASSUMPTIONS!$C$21-ASSUMPTIONS!$C$18*ASSUMPTIONS!$C$22)*(1+H19)^5*(1+K19)/(I19-K19)/(1+I19)^5)-DCF!$C$12)/ASSUMPTIONS!$C$7 | N19: =MIN(L7:L2006)+(0.3333333333333333)*(MAX(L7:L2006)-MIN(L7:L2006)) | O19: =COUNTIFS(L7:L2006,">"&N18,L7:L2006,"<="&N19)
B20: Year 1 | C20: =C13*C8*(1-ASSUMPTIONS!$C$20)+C13*ASSUMPTIONS!$C$21-C13*ASSUMPTIONS!$C$22-(C13-ASSUMPTIONS!$C$18)*ASSUMPTIONS!$C$23 | D20: =D13*D8*(1-ASSUMPTIONS!$C$20)+D13*ASSUMPTIONS!$C$21-D13*ASSUMPTIONS!$C$22-(D13-ASSUMPTIONS!$C$18)*ASSUMPTIONS!$C$23 | E20: =E13*E8*(1-ASSUMPTIONS!$C$20)+E13*ASSUMPTIONS!$C$21-E13*ASSUMPTIONS!$C$22-(E13-ASSUMPTIONS!$C$18)*ASSUMPTIONS!$C$23 | H20: =_xlfn.NORM.INV(RAND(),AVERAGE(ASSUMPTIONS!$C$38,ASSUMPTIONS!$C$39,ASSUMPTIONS!$C$40,ASSUMPTIONS!$C$41,ASSUMPTIONS!$C$42),ASSUMPTIONS!$C$68) | I20: =MAX(_xlfn.NORM.INV(RAND(),DCF!$C$11,ASSUMPTIONS!$C$69),K20+0.005) | J20: =_xlfn.NORM.INV(RAND(),ASSUMPTIONS!$C$19,ASSUMPTIONS!$C$70) | K20: =_xlfn.NORM.INV(RAND(),ASSUMPTIONS!$C$43,ASSUMPTIONS!$C$71) | L20: =(((ASSUMPTIONS!$C$18*J20*(1-ASSUMPTIONS!$C$20)+ASSUMPTIONS!$C$18*ASSUMPTIONS!$C$21-ASSUMPTIONS!$C$18*ASSUMPTIONS!$C$22)*(1+H20)*(1-((1+H20)/(1+I20))^5)/(I20-H20))+((ASSUMPTIONS!$C$18*J20*(1-ASSUMPTIONS!$C$20)+ASSUMPTIONS!$C$18*ASSUMPTIONS!$C$21-ASSUMPTIONS!$C$18*ASSUMPTIONS!$C$22)*(1+H20)^5*(1+K20)/(I20-K20)/(1+I20)^5)-DCF!$C$12)/ASSUMPTIONS!$C$7 | N20: =MIN(L7:L2006)+(0.4166666666666667)*(MAX(L7:L2006)-MIN(L7:L2006)) | O20: =COUNTIFS(L7:L2006,">"&N19,L7:L2006,"<="&N20)
B21: Year 2 | C21: =C14*C8*(1-ASSUMPTIONS!$C$20)+C14*ASSUMPTIONS!$C$21-C14*ASSUMPTIONS!$C$22-(C14-C13)*ASSUMPTIONS!$C$23 | D21: =D14*D8*(1-ASSUMPTIONS!$C$20)+D14*ASSUMPTIONS!$C$21-D14*ASSUMPTIONS!$C$22-(D14-D13)*ASSUMPTIONS!$C$23 | E21: =E14*E8*(1-ASSUMPTIONS!$C$20)+E14*ASSUMPTIONS!$C$21-E14*ASSUMPTIONS!$C$22-(E14-E13)*ASSUMPTIONS!$C$23 | H21: =_xlfn.NORM.INV(RAND(),AVERAGE(ASSUMPTIONS!$C$38,ASSUMPTIONS!$C$39,ASSUMPTIONS!$C$40,ASSUMPTIONS!$C$41,ASSUMPTIONS!$C$42),ASSUMPTIONS!$C$68) | I21: =MAX(_xlfn.NORM.INV(RAND(),DCF!$C$11,ASSUMPTIONS!$C$69),K21+0.005) | J21: =_xlfn.NORM.INV(RAND(),ASSUMPTIONS!$C$19,ASSUMPTIONS!$C$70) | K21: =_xlfn.NORM.INV(RAND(),ASSUMPTIONS!$C$43,ASSUMPTIONS!$C$71) | L21: =(((ASSUMPTIONS!$C$18*J21*(1-ASSUMPTIONS!$C$20)+ASSUMPTIONS!$C$18*ASSUMPTIONS!$C$21-ASSUMPTIONS!$C$18*ASSUMPTIONS!$C$22)*(1+H21)*(1-((1+H21)/(1+I21))^5)/(I21-H21))+((ASSUMPTIONS!$C$18*J21*(1-ASSUMPTIONS!$C$20)+ASSUMPTIONS!$C$18*ASSUMPTIONS!$C$21-ASSUMPTIONS!$C$18*ASSUMPTIONS!$C$22)*(1+H21)^5*(1+K21)/(I21-K21)/(1+I21)^5)-DCF!$C$12)/ASSUMPTIONS!$C$7 | N21: =MIN(L7:L2006)+(0.5)*(MAX(L7:L2006)-MIN(L7:L2006)) | O21: =COUNTIFS(L7:L2006,">"&N20,L7:L2006,"<="&N21)
B22: Year 3 | C22: =C15*C8*(1-ASSUMPTIONS!$C$20)+C15*ASSUMPTIONS!$C$21-C15*ASSUMPTIONS!$C$22-(C15-C14)*ASSUMPTIONS!$C$23 | D22: =D15*D8*(1-ASSUMPTIONS!$C$20)+D15*ASSUMPTIONS!$C$21-D15*ASSUMPTIONS!$C$22-(D15-D14)*ASSUMPTIONS!$C$23 | E22: =E15*E8*(1-ASSUMPTIONS!$C$20)+E15*ASSUMPTIONS!$C$21-E15*ASSUMPTIONS!$C$22-(E15-E14)*ASSUMPTIONS!$C$23 | H22: =_xlfn.NORM.INV(RAND(),AVERAGE(ASSUMPTIONS!$C$38,ASSUMPTIONS!$C$39,ASSUMPTIONS!$C$40,ASSUMPTIONS!$C$41,ASSUMPTIONS!$C$42),ASSUMPTIONS!$C$68) | I22: =MAX(_xlfn.NORM.INV(RAND(),DCF!$C$11,ASSUMPTIONS!$C$69),K22+0.005) | J22: =_xlfn.NORM.INV(RAND(),ASSUMPTIONS!$C$19,ASSUMPTIONS!$C$70) | K22: =_xlfn.NORM.INV(RAND(),ASSUMPTIONS!$C$43,ASSUMPTIONS!$C$71) | L22: =(((ASSUMPTIONS!$C$18*J22*(1-ASSUMPTIONS!$C$20)+ASSUMPTIONS!$C$18*ASSUMPTIONS!$C$21-ASSUMPTIONS!$C$18*ASSUMPTIONS!$C$22)*(1+H22)*(1-((1+H22)/(1+I22))^5)/(I22-H22))+((ASSUMPTIONS!$C$18*J22*(1-ASSUMPTIONS!$C$20)+ASSUMPTIONS!$C$18*ASSUMPTIONS!$C$21-ASSUMPTIONS!$C$18*ASSUMPTIONS!$C$22)*(1+H22)^5*(1+K22)/(I22-K22)/(1+I22)^5)-DCF!$C$12)/ASSUMPTIONS!$C$7 | N22: =MIN(L7:L2006)+(0.5833333333333334)*(MAX(L7:L2006)-MIN(L7:L2006)) | O22: =COUNTIFS(L7:L2006,">"&N21,L7:L2006,"<="&N22) | Q22: K E L L Y P O S I T I O N S I Z I N G
B23: Year 4 | C23: =C16*C8*(1-ASSUMPTIONS!$C$20)+C16*ASSUMPTIONS!$C$21-C16*ASSUMPTIONS!$C$22-(C16-C15)*ASSUMPTIONS!$C$23 | D23: =D16*D8*(1-ASSUMPTIONS!$C$20)+D16*ASSUMPTIONS!$C$21-D16*ASSUMPTIONS!$C$22-(D16-D15)*ASSUMPTIONS!$C$23 | E23: =E16*E8*(1-ASSUMPTIONS!$C$20)+E16*ASSUMPTIONS!$C$21-E16*ASSUMPTIONS!$C$22-(E16-E15)*ASSUMPTIONS!$C$23 | H23: =_xlfn.NORM.INV(RAND(),AVERAGE(ASSUMPTIONS!$C$38,ASSUMPTIONS!$C$39,ASSUMPTIONS!$C$40,ASSUMPTIONS!$C$41,ASSUMPTIONS!$C$42),ASSUMPTIONS!$C$68) | I23: =MAX(_xlfn.NORM.INV(RAND(),DCF!$C$11,ASSUMPTIONS!$C$69),K23+0.005) | J23: =_xlfn.NORM.INV(RAND(),ASSUMPTIONS!$C$19,ASSUMPTIONS!$C$70) | K23: =_xlfn.NORM.INV(RAND(),ASSUMPTIONS!$C$43,ASSUMPTIONS!$C$71) | L23: =(((ASSUMPTIONS!$C$18*J23*(1-ASSUMPTIONS!$C$20)+ASSUMPTIONS!$C$18*ASSUMPTIONS!$C$21-ASSUMPTIONS!$C$18*ASSUMPTIONS!$C$22)*(1+H23)*(1-((1+H23)/(1+I23))^5)/(I23-H23))+((ASSUMPTIONS!$C$18*J23*(1-ASSUMPTIONS!$C$20)+ASSUMPTIONS!$C$18*ASSUMPTIONS!$C$21-ASSUMPTIONS!$C$18*ASSUMPTIONS!$C$22)*(1+H23)^5*(1+K23)/(I23-K23)/(1+I23)^5)-DCF!$C$12)/ASSUMPTIONS!$C$7 | N23: =MIN(L7:L2006)+(0.6666666666666666)*(MAX(L7:L2006)-MIN(L7:L2006)) | O23: =COUNTIFS(L7:L2006,">"&N22,L7:L2006,"<="&N23) | Q23: p = clamp(0.5+MoS,0.10,0.90) | R23: =MIN(0.90,MAX(0.10,0.5+DASHBOARD!$C$10))
B24: Year 5 | C24: =C17*C8*(1-ASSUMPTIONS!$C$20)+C17*ASSUMPTIONS!$C$21-C17*ASSUMPTIONS!$C$22-(C17-C16)*ASSUMPTIONS!$C$23 | D24: =D17*D8*(1-ASSUMPTIONS!$C$20)+D17*ASSUMPTIONS!$C$21-D17*ASSUMPTIONS!$C$22-(D17-D16)*ASSUMPTIONS!$C$23 | E24: =E17*E8*(1-ASSUMPTIONS!$C$20)+E17*ASSUMPTIONS!$C$21-E17*ASSUMPTIONS!$C$22-(E17-E16)*ASSUMPTIONS!$C$23 | H24: =_xlfn.NORM.INV(RAND(),AVERAGE(ASSUMPTIONS!$C$38,ASSUMPTIONS!$C$39,ASSUMPTIONS!$C$40,ASSUMPTIONS!$C$41,ASSUMPTIONS!$C$42),ASSUMPTIONS!$C$68) | I24: =MAX(_xlfn.NORM.INV(RAND(),DCF!$C$11,ASSUMPTIONS!$C$69),K24+0.005) | J24: =_xlfn.NORM.INV(RAND(),ASSUMPTIONS!$C$19,ASSUMPTIONS!$C$70) | K24: =_xlfn.NORM.INV(RAND(),ASSUMPTIONS!$C$43,ASSUMPTIONS!$C$71) | L24: =(((ASSUMPTIONS!$C$18*J24*(1-ASSUMPTIONS!$C$20)+ASSUMPTIONS!$C$18*ASSUMPTIONS!$C$21-ASSUMPTIONS!$C$18*ASSUMPTIONS!$C$22)*(1+H24)*(1-((1+H24)/(1+I24))^5)/(I24-H24))+((ASSUMPTIONS!$C$18*J24*(1-ASSUMPTIONS!$C$20)+ASSUMPTIONS!$C$18*ASSUMPTIONS!$C$21-ASSUMPTIONS!$C$18*ASSUMPTIONS!$C$22)*(1+H24)^5*(1+K24)/(I24-K24)/(1+I24)^5)-DCF!$C$12)/ASSUMPTIONS!$C$7 | N24: =MIN(L7:L2006)+(0.75)*(MAX(L7:L2006)-MIN(L7:L2006)) | O24: =COUNTIFS(L7:L2006,">"&N23,L7:L2006,"<="&N24) | Q24: b = FV/price - 1 (upside) | R24: =DASHBOARD!$C$8/ASSUMPTIONS!$C$6-1
H25: =_xlfn.NORM.INV(RAND(),AVERAGE(ASSUMPTIONS!$C$38,ASSUMPTIONS!$C$39,ASSUMPTIONS!$C$40,ASSUMPTIONS!$C$41,ASSUMPTIONS!$C$42),ASSUMPTIONS!$C$68) | I25: =MAX(_xlfn.NORM.INV(RAND(),DCF!$C$11,ASSUMPTIONS!$C$69),K25+0.005) | J25: =_xlfn.NORM.INV(RAND(),ASSUMPTIONS!$C$19,ASSUMPTIONS!$C$70) | K25: =_xlfn.NORM.INV(RAND(),ASSUMPTIONS!$C$43,ASSUMPTIONS!$C$71) | L25: =(((ASSUMPTIONS!$C$18*J25*(1-ASSUMPTIONS!$C$20)+ASSUMPTIONS!$C$18*ASSUMPTIONS!$C$21-ASSUMPTIONS!$C$18*ASSUMPTIONS!$C$22)*(1+H25)*(1-((1+H25)/(1+I25))^5)/(I25-H25))+((ASSUMPTIONS!$C$18*J25*(1-ASSUMPTIONS!$C$20)+ASSUMPTIONS!$C$18*ASSUMPTIONS!$C$21-ASSUMPTIONS!$C$18*ASSUMPTIONS!$C$22)*(1+H25)^5*(1+K25)/(I25-K25)/(1+I25)^5)-DCF!$C$12)/ASSUMPTIONS!$C$7 | N25: =MIN(L7:L2006)+(0.8333333333333334)*(MAX(L7:L2006)-MIN(L7:L2006)) | O25: =COUNTIFS(L7:L2006,">"&N24,L7:L2006,"<="&N25) | Q25: L = downside loss | R25: =ASSUMPTIONS!$C$72
B26: Sum PV(FCFF) | C26: =C20/(1+C9)^1+C21/(1+C9)^2+C22/(1+C9)^3+C23/(1+C9)^4+C24/(1+C9)^5 | D26: =D20/(1+D9)^1+D21/(1+D9)^2+D22/(1+D9)^3+D23/(1+D9)^4+D24/(1+D9)^5 | E26: =E20/(1+E9)^1+E21/(1+E9)^2+E22/(1+E9)^3+E23/(1+E9)^4+E24/(1+E9)^5 | H26: =_xlfn.NORM.INV(RAND(),AVERAGE(ASSUMPTIONS!$C$38,ASSUMPTIONS!$C$39,ASSUMPTIONS!$C$40,ASSUMPTIONS!$C$41,ASSUMPTIONS!$C$42),ASSUMPTIONS!$C$68) | I26: =MAX(_xlfn.NORM.INV(RAND(),DCF!$C$11,ASSUMPTIONS!$C$69),K26+0.005) | J26: =_xlfn.NORM.INV(RAND(),ASSUMPTIONS!$C$19,ASSUMPTIONS!$C$70) | K26: =_xlfn.NORM.INV(RAND(),ASSUMPTIONS!$C$43,ASSUMPTIONS!$C$71) | L26: =(((ASSUMPTIONS!$C$18*J26*(1-ASSUMPTIONS!$C$20)+ASSUMPTIONS!$C$18*ASSUMPTIONS!$C$21-ASSUMPTIONS!$C$18*ASSUMPTIONS!$C$22)*(1+H26)*(1-((1+H26)/(1+I26))^5)/(I26-H26))+((ASSUMPTIONS!$C$18*J26*(1-ASSUMPTIONS!$C$20)+ASSUMPTIONS!$C$18*ASSUMPTIONS!$C$21-ASSUMPTIONS!$C$18*ASSUMPTIONS!$C$22)*(1+H26)^5*(1+K26)/(I26-K26)/(1+I26)^5)-DCF!$C$12)/ASSUMPTIONS!$C$7 | N26: =MIN(L7:L2006)+(0.9166666666666666)*(MAX(L7:L2006)-MIN(L7:L2006)) | O26: =COUNTIFS(L7:L2006,">"&N25,L7:L2006,"<="&N26) | Q26: f* = (p*b-(1-p)*L)/(b*L) | R26: =IF(R24*R25=0,0,(R23*R24-(1-R23)*R25)/(R24*R25)) | S26: raw f*
B27: EBITDA Year 5 | C27: =C17*(C8+ASSUMPTIONS!$C$21) | D27: =D17*(D8+ASSUMPTIONS!$C$21) | E27: =E17*(E8+ASSUMPTIONS!$C$21) | H27: =_xlfn.NORM.INV(RAND(),AVERAGE(ASSUMPTIONS!$C$38,ASSUMPTIONS!$C$39,ASSUMPTIONS!$C$40,ASSUMPTIONS!$C$41,ASSUMPTIONS!$C$42),ASSUMPTIONS!$C$68) | I27: =MAX(_xlfn.NORM.INV(RAND(),DCF!$C$11,ASSUMPTIONS!$C$69),K27+0.005) | J27: =_xlfn.NORM.INV(RAND(),ASSUMPTIONS!$C$19,ASSUMPTIONS!$C$70) | K27: =_xlfn.NORM.INV(RAND(),ASSUMPTIONS!$C$43,ASSUMPTIONS!$C$71) | L27: =(((ASSUMPTIONS!$C$18*J27*(1-ASSUMPTIONS!$C$20)+ASSUMPTIONS!$C$18*ASSUMPTIONS!$C$21-ASSUMPTIONS!$C$18*ASSUMPTIONS!$C$22)*(1+H27)*(1-((1+H27)/(1+I27))^5)/(I27-H27))+((ASSUMPTIONS!$C$18*J27*(1-ASSUMPTIONS!$C$20)+ASSUMPTIONS!$C$18*ASSUMPTIONS!$C$21-ASSUMPTIONS!$C$18*ASSUMPTIONS!$C$22)*(1+H27)^5*(1+K27)/(I27-K27)/(1+I27)^5)-DCF!$C$12)/ASSUMPTIONS!$C$7 | N27: =MIN(L7:L2006)+(1.0)*(MAX(L7:L2006)-MIN(L7:L2006)) | O27: =COUNTIFS(L7:L2006,">"&N26,L7:L2006,"<="&N27) | Q27: Half-Kelly = f*/2 -> capped 25% | R27: =MIN(0.25,MAX(0,R26/2)) | S27: =MAX(0,R26/2)
B28: Terminal - Gordon | C28: =IF(C9<=ASSUMPTIONS!$C$43,0,C24*(1+ASSUMPTIONS!$C$43)/(C9-ASSUMPTIONS!$C$43)) | D28: =IF(D9<=ASSUMPTIONS!$C$43,0,D24*(1+ASSUMPTIONS!$C$43)/(D9-ASSUMPTIONS!$C$43)) | E28: =IF(E9<=ASSUMPTIONS!$C$43,0,E24*(1+ASSUMPTIONS!$C$43)/(E9-ASSUMPTIONS!$C$43)) | H28: =_xlfn.NORM.INV(RAND(),AVERAGE(ASSUMPTIONS!$C$38,ASSUMPTIONS!$C$39,ASSUMPTIONS!$C$40,ASSUMPTIONS!$C$41,ASSUMPTIONS!$C$42),ASSUMPTIONS!$C$68) | I28: =MAX(_xlfn.NORM.INV(RAND(),DCF!$C$11,ASSUMPTIONS!$C$69),K28+0.005) | J28: =_xlfn.NORM.INV(RAND(),ASSUMPTIONS!$C$19,ASSUMPTIONS!$C$70) | K28: =_xlfn.NORM.INV(RAND(),ASSUMPTIONS!$C$43,ASSUMPTIONS!$C$71) | L28: =(((ASSUMPTIONS!$C$18*J28*(1-ASSUMPTIONS!$C$20)+ASSUMPTIONS!$C$18*ASSUMPTIONS!$C$21-ASSUMPTIONS!$C$18*ASSUMPTIONS!$C$22)*(1+H28)*(1-((1+H28)/(1+I28))^5)/(I28-H28))+((ASSUMPTIONS!$C$18*J28*(1-ASSUMPTIONS!$C$20)+ASSUMPTIONS!$C$18*ASSUMPTIONS!$C$21-ASSUMPTIONS!$C$18*ASSUMPTIONS!$C$22)*(1+H28)^5*(1+K28)/(I28-K28)/(1+I28)^5)-DCF!$C$12)/ASSUMPTIONS!$C$7 | Q28: Full Kelly = f* -> capped 25% | R28: =MIN(0.25,MAX(0,R26)) | S28: =MAX(0,R26)
B29: Terminal - Exit mult | C29: =C27*C10 | D29: =D27*D10 | E29: =E27*E10 | H29: =_xlfn.NORM.INV(RAND(),AVERAGE(ASSUMPTIONS!$C$38,ASSUMPTIONS!$C$39,ASSUMPTIONS!$C$40,ASSUMPTIONS!$C$41,ASSUMPTIONS!$C$42),ASSUMPTIONS!$C$68) | I29: =MAX(_xlfn.NORM.INV(RAND(),DCF!$C$11,ASSUMPTIONS!$C$69),K29+0.005) | J29: =_xlfn.NORM.INV(RAND(),ASSUMPTIONS!$C$19,ASSUMPTIONS!$C$70) | K29: =_xlfn.NORM.INV(RAND(),ASSUMPTIONS!$C$43,ASSUMPTIONS!$C$71) | L29: =(((ASSUMPTIONS!$C$18*J29*(1-ASSUMPTIONS!$C$20)+ASSUMPTIONS!$C$18*ASSUMPTIONS!$C$21-ASSUMPTIONS!$C$18*ASSUMPTIONS!$C$22)*(1+H29)*(1-((1+H29)/(1+I29))^5)/(I29-H29))+((ASSUMPTIONS!$C$18*J29*(1-ASSUMPTIONS!$C$20)+ASSUMPTIONS!$C$18*ASSUMPTIONS!$C$21-ASSUMPTIONS!$C$18*ASSUMPTIONS!$C$22)*(1+H29)^5*(1+K29)/(I29-K29)/(1+I29)^5)-DCF!$C$12)/ASSUMPTIONS!$C$7
B30: Blended terminal (avg) | C30: =AVERAGE(C28,C29) | D30: =AVERAGE(D28,D29) | E30: =AVERAGE(E28,E29) | H30: =_xlfn.NORM.INV(RAND(),AVERAGE(ASSUMPTIONS!$C$38,ASSUMPTIONS!$C$39,ASSUMPTIONS!$C$40,ASSUMPTIONS!$C$41,ASSUMPTIONS!$C$42),ASSUMPTIONS!$C$68) | I30: =MAX(_xlfn.NORM.INV(RAND(),DCF!$C$11,ASSUMPTIONS!$C$69),K30+0.005) | J30: =_xlfn.NORM.INV(RAND(),ASSUMPTIONS!$C$19,ASSUMPTIONS!$C$70) | K30: =_xlfn.NORM.INV(RAND(),ASSUMPTIONS!$C$43,ASSUMPTIONS!$C$71) | L30: =(((ASSUMPTIONS!$C$18*J30*(1-ASSUMPTIONS!$C$20)+ASSUMPTIONS!$C$18*ASSUMPTIONS!$C$21-ASSUMPTIONS!$C$18*ASSUMPTIONS!$C$22)*(1+H30)*(1-((1+H30)/(1+I30))^5)/(I30-H30))+((ASSUMPTIONS!$C$18*J30*(1-ASSUMPTIONS!$C$20)+ASSUMPTIONS!$C$18*ASSUMPTIONS!$C$21-ASSUMPTIONS!$C$18*ASSUMPTIONS!$C$22)*(1+H30)^5*(1+K30)/(I30-K30)/(1+I30)^5)-DCF!$C$12)/ASSUMPTIONS!$C$7
B31: PV of terminal | C31: =C30/(1+C9)^5 | D31: =D30/(1+D9)^5 | E31: =E30/(1+E9)^5 | H31: =_xlfn.NORM.INV(RAND(),AVERAGE(ASSUMPTIONS!$C$38,ASSUMPTIONS!$C$39,ASSUMPTIONS!$C$40,ASSUMPTIONS!$C$41,ASSUMPTIONS!$C$42),ASSUMPTIONS!$C$68) | I31: =MAX(_xlfn.NORM.INV(RAND(),DCF!$C$11,ASSUMPTIONS!$C$69),K31+0.005) | J31: =_xlfn.NORM.INV(RAND(),ASSUMPTIONS!$C$19,ASSUMPTIONS!$C$70) | K31: =_xlfn.NORM.INV(RAND(),ASSUMPTIONS!$C$43,ASSUMPTIONS!$C$71) | L31: =(((ASSUMPTIONS!$C$18*J31*(1-ASSUMPTIONS!$C$20)+ASSUMPTIONS!$C$18*ASSUMPTIONS!$C$21-ASSUMPTIONS!$C$18*ASSUMPTIONS!$C$22)*(1+H31)*(1-((1+H31)/(1+I31))^5)/(I31-H31))+((ASSUMPTIONS!$C$18*J31*(1-ASSUMPTIONS!$C$20)+ASSUMPTIONS!$C$18*ASSUMPTIONS!$C$21-ASSUMPTIONS!$C$18*ASSUMPTIONS!$C$22)*(1+H31)^5*(1+K31)/(I31-K31)/(1+I31)^5)-DCF!$C$12)/ASSUMPTIONS!$C$7
B32: Enterprise value | C32: =C26+C31 | D32: =D26+D31 | E32: =E26+E31 | H32: =_xlfn.NORM.INV(RAND(),AVERAGE(ASSUMPTIONS!$C$38,ASSUMPTIONS!$C$39,ASSUMPTIONS!$C$40,ASSUMPTIONS!$C$41,ASSUMPTIONS!$C$42),ASSUMPTIONS!$C$68) | I32: =MAX(_xlfn.NORM.INV(RAND(),DCF!$C$11,ASSUMPTIONS!$C$69),K32+0.005) | J32: =_xlfn.NORM.INV(RAND(),ASSUMPTIONS!$C$19,ASSUMPTIONS!$C$70) | K32: =_xlfn.NORM.INV(RAND(),ASSUMPTIONS!$C$43,ASSUMPTIONS!$C$71) | L32: =(((ASSUMPTIONS!$C$18*J32*(1-ASSUMPTIONS!$C$20)+ASSUMPTIONS!$C$18*ASSUMPTIONS!$C$21-ASSUMPTIONS!$C$18*ASSUMPTIONS!$C$22)*(1+H32)*(1-((1+H32)/(1+I32))^5)/(I32-H32))+((ASSUMPTIONS!$C$18*J32*(1-ASSUMPTIONS!$C$20)+ASSUMPTIONS!$C$18*ASSUMPTIONS!$C$21-ASSUMPTIONS!$C$18*ASSUMPTIONS!$C$22)*(1+H32)^5*(1+K32)/(I32-K32)/(1+I32)^5)-DCF!$C$12)/ASSUMPTIONS!$C$7
B33: Equity value | C33: =C32-DCF!$C$12 | D33: =D32-DCF!$C$12 | E33: =E32-DCF!$C$12 | H33: =_xlfn.NORM.INV(RAND(),AVERAGE(ASSUMPTIONS!$C$38,ASSUMPTIONS!$C$39,ASSUMPTIONS!$C$40,ASSUMPTIONS!$C$41,ASSUMPTIONS!$C$42),ASSUMPTIONS!$C$68) | I33: =MAX(_xlfn.NORM.INV(RAND(),DCF!$C$11,ASSUMPTIONS!$C$69),K33+0.005) | J33: =_xlfn.NORM.INV(RAND(),ASSUMPTIONS!$C$19,ASSUMPTIONS!$C$70) | K33: =_xlfn.NORM.INV(RAND(),ASSUMPTIONS!$C$43,ASSUMPTIONS!$C$71) | L33: =(((ASSUMPTIONS!$C$18*J33*(1-ASSUMPTIONS!$C$20)+ASSUMPTIONS!$C$18*ASSUMPTIONS!$C$21-ASSUMPTIONS!$C$18*ASSUMPTIONS!$C$22)*(1+H33)*(1-((1+H33)/(1+I33))^5)/(I33-H33))+((ASSUMPTIONS!$C$18*J33*(1-ASSUMPTIONS!$C$20)+ASSUMPTIONS!$C$18*ASSUMPTIONS!$C$21-ASSUMPTIONS!$C$18*ASSUMPTIONS!$C$22)*(1+H33)^5*(1+K33)/(I33-K33)/(1+I33)^5)-DCF!$C$12)/ASSUMPTIONS!$C$7
B34: Fair value $/sh | C34: =C33/ASSUMPTIONS!$C$7 | D34: =D33/ASSUMPTIONS!$C$7 | E34: =E33/ASSUMPTIONS!$C$7 | H34: =_xlfn.NORM.INV(RAND(),AVERAGE(ASSUMPTIONS!$C$38,ASSUMPTIONS!$C$39,ASSUMPTIONS!$C$40,ASSUMPTIONS!$C$41,ASSUMPTIONS!$C$42),ASSUMPTIONS!$C$68) | I34: =MAX(_xlfn.NORM.INV(RAND(),DCF!$C$11,ASSUMPTIONS!$C$69),K34+0.005) | J34: =_xlfn.NORM.INV(RAND(),ASSUMPTIONS!$C$19,ASSUMPTIONS!$C$70) | K34: =_xlfn.NORM.INV(RAND(),ASSUMPTIONS!$C$43,ASSUMPTIONS!$C$71) | L34: =(((ASSUMPTIONS!$C$18*J34*(1-ASSUMPTIONS!$C$20)+ASSUMPTIONS!$C$18*ASSUMPTIONS!$C$21-ASSUMPTIONS!$C$18*ASSUMPTIONS!$C$22)*(1+H34)*(1-((1+H34)/(1+I34))^5)/(I34-H34))+((ASSUMPTIONS!$C$18*J34*(1-ASSUMPTIONS!$C$20)+ASSUMPTIONS!$C$18*ASSUMPTIONS!$C$21-ASSUMPTIONS!$C$18*ASSUMPTIONS!$C$22)*(1+H34)^5*(1+K34)/(I34-K34)/(1+I34)^5)-DCF!$C$12)/ASSUMPTIONS!$C$7
B35: Probability | C35: =ASSUMPTIONS!$C$63 | D35: =ASSUMPTIONS!$C$64 | E35: =ASSUMPTIONS!$C$65 | H35: =_xlfn.NORM.INV(RAND(),AVERAGE(ASSUMPTIONS!$C$38,ASSUMPTIONS!$C$39,ASSUMPTIONS!$C$40,ASSUMPTIONS!$C$41,ASSUMPTIONS!$C$42),ASSUMPTIONS!$C$68) | I35: =MAX(_xlfn.NORM.INV(RAND(),DCF!$C$11,ASSUMPTIONS!$C$69),K35+0.005) | J35: =_xlfn.NORM.INV(RAND(),ASSUMPTIONS!$C$19,ASSUMPTIONS!$C$70) | K35: =_xlfn.NORM.INV(RAND(),ASSUMPTIONS!$C$43,ASSUMPTIONS!$C$71) | L35: =(((ASSUMPTIONS!$C$18*J35*(1-ASSUMPTIONS!$C$20)+ASSUMPTIONS!$C$18*ASSUMPTIONS!$C$21-ASSUMPTIONS!$C$18*ASSUMPTIONS!$C$22)*(1+H35)*(1-((1+H35)/(1+I35))^5)/(I35-H35))+((ASSUMPTIONS!$C$18*J35*(1-ASSUMPTIONS!$C$20)+ASSUMPTIONS!$C$18*ASSUMPTIONS!$C$21-ASSUMPTIONS!$C$18*ASSUMPTIONS!$C$22)*(1+H35)^5*(1+K35)/(I35-K35)/(1+I35)^5)-DCF!$C$12)/ASSUMPTIONS!$C$7
B36: Prob-weighted fair value | C36: =C34*C35+D34*D35+E34*E35 | H36: =_xlfn.NORM.INV(RAND(),AVERAGE(ASSUMPTIONS!$C$38,ASSUMPTIONS!$C$39,ASSUMPTIONS!$C$40,ASSUMPTIONS!$C$41,ASSUMPTIONS!$C$42),ASSUMPTIONS!$C$68) | I36: =MAX(_xlfn.NORM.INV(RAND(),DCF!$C$11,ASSUMPTIONS!$C$69),K36+0.005) | J36: =_xlfn.NORM.INV(RAND(),ASSUMPTIONS!$C$19,ASSUMPTIONS!$C$70) | K36: =_xlfn.NORM.INV(RAND(),ASSUMPTIONS!$C$43,ASSUMPTIONS!$C$71) | L36: =(((ASSUMPTIONS!$C$18*J36*(1-ASSUMPTIONS!$C$20)+ASSUMPTIONS!$C$18*ASSUMPTIONS!$C$21-ASSUMPTIONS!$C$18*ASSUMPTIONS!$C$22)*(1+H36)*(1-((1+H36)/(1+I36))^5)/(I36-H36))+((ASSUMPTIONS!$C$18*J36*(1-ASSUMPTIONS!$C$20)+ASSUMPTIONS!$C$18*ASSUMPTIONS!$C$21-ASSUMPTIONS!$C$18*ASSUMPTIONS!$C$22)*(1+H36)^5*(1+K36)/(I36-K36)/(1+I36)^5)-DCF!$C$12)/ASSUMPTIONS!$C$7
H37: =_xlfn.NORM.INV(RAND(),AVERAGE(ASSUMPTIONS!$C$38,ASSUMPTIONS!$C$39,ASSUMPTIONS!$C$40,ASSUMPTIONS!$C$41,ASSUMPTIONS!$C$42),ASSUMPTIONS!$C$68) | I37: =MAX(_xlfn.NORM.INV(RAND(),DCF!$C$11,ASSUMPTIONS!$C$69),K37+0.005) | J37: =_xlfn.NORM.INV(RAND(),ASSUMPTIONS!$C$19,ASSUMPTIONS!$C$70) | K37: =_xlfn.NORM.INV(RAND(),ASSUMPTIONS!$C$43,ASSUMPTIONS!$C$71) | L37: =(((ASSUMPTIONS!$C$18*J37*(1-ASSUMPTIONS!$C$20)+ASSUMPTIONS!$C$18*ASSUMPTIONS!$C$21-ASSUMPTIONS!$C$18*ASSUMPTIONS!$C$22)*(1+H37)*(1-((1+H37)/(1+I37))^5)/(I37-H37))+((ASSUMPTIONS!$C$18*J37*(1-ASSUMPTIONS!$C$20)+ASSUMPTIONS!$C$18*ASSUMPTIONS!$C$21-ASSUMPTIONS!$C$18*ASSUMPTIONS!$C$22)*(1+H37)^5*(1+K37)/(I37-K37)/(1+I37)^5)-DCF!$C$12)/ASSUMPTIONS!$C$7
H38: =_xlfn.NORM.INV(RAND(),AVERAGE(ASSUMPTIONS!$C$38,ASSUMPTIONS!$C$39,ASSUMPTIONS!$C$40,ASSUMPTIONS!$C$41,ASSUMPTIONS!$C$42),ASSUMPTIONS!$C$68) | I38: =MAX(_xlfn.NORM.INV(RAND(),DCF!$C$11,ASSUMPTIONS!$C$69),K38+0.005) | J38: =_xlfn.NORM.INV(RAND(),ASSUMPTIONS!$C$19,ASSUMPTIONS!$C$70) | K38: =_xlfn.NORM.INV(RAND(),ASSUMPTIONS!$C$43,ASSUMPTIONS!$C$71) | L38: =(((ASSUMPTIONS!$C$18*J38*(1-ASSUMPTIONS!$C$20)+ASSUMPTIONS!$C$18*ASSUMPTIONS!$C$21-ASSUMPTIONS!$C$18*ASSUMPTIONS!$C$22)*(1+H38)*(1-((1+H38)/(1+I38))^5)/(I38-H38))+((ASSUMPTIONS!$C$18*J38*(1-ASSUMPTIONS!$C$20)+ASSUMPTIONS!$C$18*ASSUMPTIONS!$C$21-ASSUMPTIONS!$C$18*ASSUMPTIONS!$C$22)*(1+H38)^5*(1+K38)/(I38-K38)/(1+I38)^5)-DCF!$C$12)/ASSUMPTIONS!$C$7
